Workbook

Sheet Main (2)
D1: ca | L1: GAP
C2: KẾ HOẠCH SẢN XUẤT HÀNG NGÀY | M2: Mã tài liệu | N2: Q401-02
M3: Ngày ban hành | N3: 2022.10.01
M4: Lần ban hành | N4: 04
M5: =TODAY() -> 46130
A6: STT | B6: SỐ CHỈ THỊ THƯ | C6: MÃ SẢN PHẨM | D6: NGUYÊN VẬT LIỆU | E6: SIZE | F6: SỐ MÁY | G6: SỐ LƯỢNG CẦN SX | H6: SẢN XUẤT THỰC TẾ | I6: SẢN LƯỢNG CÒN LẠI | J6: TÌNH TRẠNG KHUÔN | K6: SẢN LƯỢNG HÔM TRƯỚC | L6: NVL CẦN | M6: SỐ LƯỢNG THIẾU -> (W24) | N6: SỐ LƯỢNG THIẾU -> (W26) | O6: NGUYÊN VẬT LIỆU | P6: Stock RM | Q6: 생산가능 수량 | R6: Master Code
A8: 1 | C8: 071245-F14W-A | D8: =IFERROR(VLOOKUP(C8,ERP!$B$1:$AN$1548,39,0),0) -> SCM435 (S)AIP | E8: =IFERROR(VLOOKUP(C8,ERP!$B$1:$AO$1548,40,0),0) -> 5.45 | F8: 1,5 | G8: 300000 | H8: 305100 | I8: =G8-H8 -> -5100 | J8: HẾT KẾ HOẠCH | L8: -139.332 | M8: =IFERROR(MIN(VLOOKUP(C8,'[1]Shortage Analysis'!C$4:U$537,19,0),0),0) -> -92352 | N8: =IFERROR(MIN(VLOOKUP(C8,'[1]Shortage Analysis'!C$4:W$537,21,0),0),0) -> -232352 | O8: =D8&E8 -> SCM435 (S)AIP5.45 | P8: =IFERROR(VLOOKUP(O8,'NVL Stock'!$N$1:$O$444,2,0),0) -> 8428 | Q8: =P8*1000/#REF! -> #REF! | R8: =VLOOKUP(C8,ERP!$B$1:$BM$1616,64,0) -> 20080
A9: 2 | B9: 603-079 | C9: 100550-YM1W-Z | D9: =IFERROR(VLOOKUP(C9,ERP!$B$1:$AN$1548,39,0),0) -> S10A HD | E9: =IFERROR(VLOOKUP(C9,ERP!$B$1:$AO$1548,40,0),0) -> 12.2 | F9: 1A | G9: 150000 | H9: 87760 | I9: =G9-H9 -> 62240 | J9: HẾT NVL | L9: 3443.1168 | M9: =IFERROR(MIN(VLOOKUP(C9,'[1]Shortage Analysis'!C$4:U$537,19,0),0),0) -> 0 | N9: =IFERROR(MIN(VLOOKUP(C9,'[1]Shortage Analysis'!C$4:W$537,21,0),0),0) -> 0 | O9: =D9&E9 -> S10A HD12.2 | P9: =IFERROR(VLOOKUP(O9,'NVL Stock'!$N$1:$O$444,2,0),0) -> 0 | Q9: =P9*1000/#REF! -> #REF! | R9: =VLOOKUP(C9,ERP!$B$1:$BM$1616,64,0) -> 20203
A10: 3 | B10: 603-080 | C10: 120300-UM1A-4AC | D10: =IFERROR(VLOOKUP(C10,ERP!$B$1:$AN$1548,39,0),0) -> S10A HD | E10: =IFERROR(VLOOKUP(C10,ERP!$B$1:$AO$1548,40,0),0) -> 10.72 | F10: 2 | G10: 200000 | H10: 173200 | I10: =G10-H10 -> 26800 | K10: 18000 | L10: 1012.236 | M10: =IFERROR(MIN(VLOOKUP(C10,'[1]Shortage Analysis'!C$4:U$537,19,0),0),0) -> -49183 | N10: =IFERROR(MIN(VLOOKUP(C10,'[1]Shortage Analysis'!C$4:W$537,21,0),0),0) -> -57157 | O10: =D10&E10 -> S10A HD10.72 | P10: =IFERROR(VLOOKUP(O10,'NVL Stock'!$N$1:$O$444,2,0),0) -> 3332 | Q10: =P10*1000/#REF! -> #REF! | R10: =VLOOKUP(C10,ERP!$B$1:$BM$1616,64,0) -> 20045
A11: 4 | C11: 8.5x60 | F11: 3 | H11: 0 | J11: TEST MẪU
A12: 5 | B12: 603-072 | C12: 080315-JM6R-DH | D12: =IFERROR(VLOOKUP(C12,ERP!$B$1:$AN$1548,39,0),0) -> STS304CU WSB | E12: =IFERROR(VLOOKUP(C12,ERP!$B$1:$AO$1548,40,0),0) -> 7.02 | F12: 4A | G12: 800000 | H12: 631300 | I12: =G12-H12 -> 168700 | K12: =24900+16000 -> 40900 | L12: 2103.689 | M12: =IFERROR(MIN(VLOOKUP(C12,'[1]Shortage Analysis'!C$4:U$537,19,0),0),0) -> -355130 | N12: =IFERROR(MIN(VLOOKUP(C12,'[1]Shortage Analysis'!C$4:W$537,21,0),0),0) -> -355130 | O12: =D12&E12 -> STS304CU WSB7.02 | P12: =IFERROR(VLOOKUP(O12,'NVL Stock'!$N$1:$O$444,2,0),0) -> 3834 | Q12: =P12*1000/#REF! -> #REF! | R12: =VLOOKUP(C12,ERP!$B$1:$BM$1616,64,0) -> 40002
A13: 6 | B13: 603-078 | C13: 100350-F51A-D | D13: =IFERROR(VLOOKUP(C13,ERP!$B$1:$AN$1548,39,0),0) -> S10A HD | E13: =IFERROR(VLOOKUP(C13,ERP!$B$1:$AO$1548,40,0),0) -> 9.96 | F13: 4 | G13: 300000 | H13: 0 | I13: =G13-H13 -> 300000 | L13: 8880 | M13: =IFERROR(MIN(VLOOKUP(C13,'[1]Shortage Analysis'!C$4:U$537,19,0),0),0) -> -284013 | N13: =IFERROR(MIN(VLOOKUP(C13,'[1]Shortage Analysis'!C$4:W$537,21,0),0),0) -> -284013 | O13: =D13&E13 -> S10A HD9.96 | P13: =IFERROR(VLOOKUP(O13,'NVL Stock'!$N$1:$O$444,2,0),0) -> 9945 | Q13: =P13*1000/#REF! -> #REF! | R13: =VLOOKUP(C13,ERP!$B$1:$BM$1616,64,0) -> 20000
A14: 7 | B14: 603-071 | C14: 080300-FM5L-DS | D14: =IFERROR(VLOOKUP(C14,ERP!$B$1:$AN$1548,39,0),0) -> STS430 WSB | E14: =IFERROR(VLOOKUP(C14,ERP!$B$1:$AO$1548,40,0),0) -> 7.02 | F14: 6 | G14: 300000 | H14: 199900 | I14: =G14-H14 -> 100100 | K14: =5000+3900 -> 8900 | L14: 1477.476 | M14: =IFERROR(MIN(VLOOKUP(C14,'[1]Shortage Analysis'!C$4:U$537,19,0),0),0) -> -477573 | N14: =IFERROR(MIN(VLOOKUP(C14,'[1]Shortage Analysis'!C$4:W$537,21,0),0),0) -> -477573 | O14: =D14&E14 -> STS430 WSB7.02 | P14: =IFERROR(VLOOKUP(O14,'NVL Stock'!$N$1:$O$444,2,0),0) -> 3629 | Q14: =P14*1000/#REF! -> #REF! | R14: =VLOOKUP(C14,ERP!$B$1:$BM$1616,64,0) -> 20005
A15: 8 | B15: 603-070 | C15: 080290-FM6R-D | D15: =IFERROR(VLOOKUP(C15,ERP!$B$1:$AN$1548,39,0),0) -> STS304CU WSB | E15: =IFERROR(VLOOKUP(C15,ERP!$B$1:$AO$1548,40,0),0) -> 7.02 | F15: 7 | G15: 200000 | H15: 89000 | I15: =G15-H15 -> 111000 | K15: =27200+6200 -> 33400 | L15: 1399.71 | M15: =IFERROR(MIN(VLOOKUP(C15,'[1]Shortage Analysis'!C$4:U$537,19,0),0),0) -> -110836 | N15: =IFERROR(MIN(VLOOKUP(C15,'[1]Shortage Analysis'!C$4:W$537,21,0),0),0) -> -110836 | O15: =D15&E15 -> STS304CU WSB7.02 | P15: =IFERROR(VLOOKUP(O15,'NVL Stock'!$N$1:$O$444,2,0),0) -> 3834 | Q15: =P15*1000/#REF! -> #REF! | R15: =VLOOKUP(C15,ERP!$B$1:$BM$1616,64,0) -> 40001
A16: 9 | B16: 602-083 | C16: 650320-F62W-SP | D16: =IFERROR(VLOOKUP(C16,ERP!$B$1:$AN$1548,39,0),0) -> S18A (S)AIP (F) | E16: =IFERROR(VLOOKUP(C16,ERP!$B$1:$AO$1548,40,0),0) -> 5.45 | F16: 7A | G16: 2000000 | H16: 1992500 | I16: =G16-H16 -> 7500 | J16: HẾT NVL | L16: 71.475 | M16: =IFERROR(MIN(VLOOKUP(C16,'[1]Shortage Analysis'!C$4:U$537,19,0),0),0) -> -1425075 | N16: =IFERROR(MIN(VLOOKUP(C16,'[1]Shortage Analysis'!C$4:W$537,21,0),0),0) -> -1425075 | O16: =D16&E16 -> S18A (S)AIP (F)5.45 | P16: =IFERROR(VLOOKUP(O16,'NVL Stock'!$N$1:$O$444,2,0),0) -> 543 | Q16: =P16*1000/#REF! -> #REF! | R16: =VLOOKUP(C16,ERP!$B$1:$BM$1616,64,0) -> 20004
A17: 10 | F17: 8 | H17: 0 | J17: ĐÀO TẠO | M17: =IFERROR(MIN(VLOOKUP(C17,'[1]Shortage Analysis'!C$4:U$537,19,0),0),0) -> 0 | N17: =IFERROR(MIN(VLOOKUP(C17,'[1]Shortage Analysis'!C$4:W$537,21,0),0),0) -> 0 | P17: =IFERROR(VLOOKUP(O17,'NVL Stock'!$N$1:$O$444,2,0),0) -> 0
A18: 11 | C18: 050195-T62W-DZ | D18: =IFERROR(VLOOKUP(C18,ERP!$B$1:$AN$1548,39,0),0) -> S18A SAIP (F) | E18: =IFERROR(VLOOKUP(C18,ERP!$B$1:$AO$1548,40,0),0) -> 7.05 | F18: 8A | H18: 0 | J18: HẾT KẾ HOẠCH | L18: 0 | M18: =IFERROR(MIN(VLOOKUP(C18,'[1]Shortage Analysis'!C$4:U$537,19,0),0),0) -> 0 | N18: =IFERROR(MIN(VLOOKUP(C18,'[1]Shortage Analysis'!C$4:W$537,21,0),0),0) -> 0 | O18: =D18&E18 -> S18A SAIP (F)7.05 | P18: =IFERROR(VLOOKUP(O18,'NVL Stock'!$N$1:$O$444,2,0),0) -> 1073 | Q18: =P18*1000/#REF! -> #REF! | R18: =VLOOKUP(C18,ERP!$B$1:$BM$1616,64,0) -> 20061
A19: 12 | B19: 601-044 | C19: 040145-HM6H-MZ | D19: =IFERROR(VLOOKUP(C19,ERP!$B$1:$AN$1548,39,0),0) -> STS304CU WSB | E19: =IFERROR(VLOOKUP(C19,ERP!$B$1:$AO$1548,40,0),0) -> 3.45 | F19: 9A | G19: 200000 | H19: 198700 | I19: =G19-H19 -> 1300 | J19: CHỜ KẸP | K19: =31000 -> 31000 | L19: 2.873 | M19: =IFERROR(MIN(VLOOKUP(C19,'[1]Shortage Analysis'!C$4:U$537,19,0),0),0) -> -3000 | N19: =IFERROR(MIN(VLOOKUP(C19,'[1]Shortage Analysis'!C$4:W$537,21,0),0),0) -> -3000 | O19: =D19&E19 -> STS304CU WSB3.45 | P19: =IFERROR(VLOOKUP(O19,'NVL Stock'!$N$1:$O$444,2,0),0) -> 1091 | Q19: =P19*1000/#REF! -> #REF! | R19: =VLOOKUP(C19,ERP!$B$1:$BM$1616,64,0) -> 53801
A20: 13 | B20: 603-046 | C20: 040145-HM6H-MZ | D20: =IFERROR(VLOOKUP(C20,ERP!$B$1:$AN$1548,39,0),0) -> STS304CU WSB | E20: =IFERROR(VLOOKUP(C20,ERP!$B$1:$AO$1548,40,0),0) -> 3.45 | G20: 200000 | H20: 0 | I20: =G20-H20 -> 200000 | L20: 442 | M20: =IFERROR(MIN(VLOOKUP(C20,'[1]Shortage Analysis'!C$4:U$537,19,0),0),0) -> -3000 | N20: =IFERROR(MIN(VLOOKUP(C20,'[1]Shortage Analysis'!C$4:W$537,21,0),0),0) -> -3000 | O20: =D20&E20 -> STS304CU WSB3.45 | P20: =IFERROR(VLOOKUP(O20,'NVL Stock'!$N$1:$O$444,2,0),0) -> 1091 | Q20: =P20*1000/#REF! -> #REF! | R20: =VLOOKUP(C20,ERP!$B$1:$BM$1616,64,0) -> 53801
A21: 14 | B21: 604-005 | C21: 030180-TY2W-T | D21: =IFERROR(VLOOKUP(C21,ERP!$B$1:$AN$1548,39,0),0) -> S18A SAIP (F) | E21: =IFERROR(VLOOKUP(C21,ERP!$B$1:$AO$1548,40,0),0) -> 3.2 | F21: 9 | G21: 200000 | H21: 16000 | I21: =G21-H21 -> 184000 | L21: 163.76 | M21: =IFERROR(MIN(VLOOKUP(C21,'[1]Shortage Analysis'!C$4:U$537,19,0),0),0) -> -183000 | N21: =IFERROR(MIN(VLOOKUP(C21,'[1]Shortage Analysis'!C$4:W$537,21,0),0),0) -> -183000 | O21: =D21&E21 -> S18A SAIP (F)3.2 | P21: =IFERROR(VLOOKUP(O21,'NVL Stock'!$N$1:$O$444,2,0),0) -> 12792 | Q21: =P21*1000/#REF! -> #REF! | R21: =VLOOKUP(C21,ERP!$B$1:$BM$1616,64,0) -> 55017
A22: 15 | B22: 603-059 | C22: 050160-T12W | D22: =IFERROR(VLOOKUP(C22,ERP!$B$1:$AN$1548,39,0),0) -> S18A SAIP (F) | E22: =IFERROR(VLOOKUP(C22,ERP!$B$1:$AO$1548,40,0),0) -> 3.95 | F22: 10 | G22: 200000 | H22: 84900 | I22: =G22-H22 -> 115100 | K22: =23500+5100 -> 28600 | L22: 347.602 | M22: =IFERROR(MIN(VLOOKUP(C22,'[1]Shortage Analysis'!C$4:U$537,19,0),0),0) -> -101338 | N22: =IFERROR(MIN(VLOOKUP(C22,'[1]Shortage Analysis'!C$4:W$537,21,0),0),0) -> -101338 | O22: =D22&E22 -> S18A SAIP (F)3.95 | P22: =IFERROR(VLOOKUP(O22,'NVL Stock'!$N$1:$O$444,2,0),0) -> 899 | Q22: =P22*1000/#REF! -> #REF! | R22: =VLOOKUP(C22,ERP!$B$1:$BM$1616,64,0) -> 20017
A23: 16 | C23: 050200-FS2W-P | D23: =IFERROR(VLOOKUP(C23,ERP!$B$1:$AN$1548,39,0),0) -> S18A SAIP (F) | E23: =IFERROR(VLOOKUP(C23,ERP!$B$1:$AO$1548,40,0),0) -> 4.55 | F23: 11 | G23: 500000 | H23: 504600 | I23: =G23-H23 -> -4600 | J23: TEST KHUÔN RL | L23: -19.458 | M23: =IFERROR(MIN(VLOOKUP(C23,'[1]Shortage Analysis'!C$4:U$537,19,0),0),0) -> -135905 | N23: =IFERROR(MIN(VLOOKUP(C23,'[1]Shortage Analysis'!C$4:W$537,21,0),0),0) -> -135905 | O23: =D23&E23 -> S18A SAIP (F)4.55 | P23: =IFERROR(VLOOKUP(O23,'NVL Stock'!$N$1:$O$444,2,0),0) -> 674 | Q23: =P23*1000/#REF! -> #REF! | R23: =VLOOKUP(C23,ERP!$B$1:$BM$1616,64,0) -> 20070
A24: 17 | C24: 040600-UM1W-PQ | D24: STS304 | E24: 3.45 | G24: 400 | H24: 0 | I24: =G24-H24 -> 400 | J24: STS304 | M24: =IFERROR(MIN(VLOOKUP(C24,'[1]Shortage Analysis'!C$4:U$537,19,0),0),0) -> 0 | N24: =IFERROR(MIN(VLOOKUP(C24,'[1]Shortage Analysis'!C$4:W$537,21,0),0),0) -> 0
A25: 18 | B25: 602-065 | C25: 060200-F12W-P | D25: =IFERROR(VLOOKUP(C25,ERP!$B$1:$AN$1548,39,0),0) -> S18A SAIP (F) | E25: =IFERROR(VLOOKUP(C25,ERP!$B$1:$AO$1548,40,0),0) -> 4.85 | F25: 12 | G25: 500000 | H25: 403500 | I25: =G25-H25 -> 96500 | K25: =40500 -> 40500 | L25: 507.59 | M25: =IFERROR(MIN(VLOOKUP(C25,'[1]Shortage Analysis'!C$4:U$537,19,0),0),0) -> -370586 | N25: =IFERROR(MIN(VLOOKUP(C25,'[1]Shortage Analysis'!C$4:W$537,21,0),0),0) -> -370586 | O25: =D25&E25 -> S18A SAIP (F)4.85 | P25: =IFERROR(VLOOKUP(O25,'NVL Stock'!$N$1:$O$444,2,0),0) -> 2302 | Q25: =P25*1000/#REF! -> #REF! | R25: =VLOOKUP(C25,ERP!$B$1:$BM$1616,64,0) -> 40043
A26: 19 | B26: 603-055 | C26: 040400-J16H-D | D26: =IFERROR(VLOOKUP(C26,ERP!$B$1:$AN$1548,39,0),0) -> STS304CU WSA | E26: =IFERROR(VLOOKUP(C26,ERP!$B$1:$AO$1548,40,0),0) -> 3.25 | F26: 13 | G26: 200000 | H26: 0 | I26: =G26-H26 -> 200000 | L26: 578 | M26: =IFERROR(MIN(VLOOKUP(C26,'[1]Shortage Analysis'!C$4:U$537,19,0),0),0) -> -263648 | N26: =IFERROR(MIN(VLOOKUP(C26,'[1]Shortage Analysis'!C$4:W$537,21,0),0),0) -> -263648 | O26: =D26&E26 -> STS304CU WSA3.25 | P26: =IFERROR(VLOOKUP(O26,'NVL Stock'!$N$1:$O$444,2,0),0) -> 791 | Q26: =P26*1000/#REF! -> #REF! | R26: =VLOOKUP(C26,ERP!$B$1:$BM$1616,64,0) -> 40057
A27: 20 | B27: 510-067 | C27: 060090-ZE1W-C | D27: =IFERROR(VLOOKUP(C27,ERP!$B$1:$AN$1548,39,0),0) -> S10A HD | E27: =IFERROR(VLOOKUP(C27,ERP!$B$1:$AO$1548,40,0),0) -> 5.9 | F27: 14 | G27: 20000 | H27: 4200 | I27: =G27-H27 -> 15800 | L27: 33.18 | M27: =IFERROR(MIN(VLOOKUP(C27,'[1]Shortage Analysis'!C$4:U$537,19,0),0),0) -> -990.8 | N27: =IFERROR(MIN(VLOOKUP(C27,'[1]Shortage Analysis'!C$4:W$537,21,0),0),0) -> -990.8 | O27: =D27&E27 -> S10A HD5.9 | P27: =IFERROR(VLOOKUP(O27,'NVL Stock'!$N$1:$O$444,2,0),0) -> 112 | Q27: =P27*1000/#REF! -> #REF! | R27: =VLOOKUP(C27,ERP!$B$1:$BM$1616,64,0) -> 52500
A28: 21 | F28: 9B | H28: 0 | J28: MÁY HƯ | L28: 0 | M28: =IFERROR(MIN(VLOOKUP(C28,'[1]Shortage Analysis'!C$4:U$537,19,0),0),0) -> 0 | N28: =IFERROR(MIN(VLOOKUP(C28,'[1]Shortage Analysis'!C$4:W$537,21,0),0),0) -> 0 | O28: =D28&E28 | P28: =IFERROR(VLOOKUP(O28,'NVL Stock'!$N$1:$O$444,2,0),0) -> 0 | Q28: =P28*1000/#REF! -> #REF! | R28: =VLOOKUP(C28,ERP!$B$1:$BM$1616,64,0) -> 0
A29: 22 | B29: 603-040 | C29: 040120-TP2W-S | D29: =IFERROR(VLOOKUP(C29,ERP!$B$1:$AN$1548,39,0),0) -> S18A SAIP (F) | E29: =IFERROR(VLOOKUP(C29,ERP!$B$1:$AO$1548,40,0),0) -> 3.2 | F29: 15,31 | G29: 3500000 | H29: 1881700 | I29: =G29-H29 -> 1618300 | K29: =17000+23000+30000+23000 -> 93000 | L29: 2443.633 | M29: =IFERROR(MIN(VLOOKUP(C29,'[1]Shortage Analysis'!C$4:U$537,19,0),0),0) -> -5472582 | N29: =IFERROR(MIN(VLOOKUP(C29,'[1]Shortage Analysis'!C$4:W$537,21,0),0),0) -> -5719761 | O29: =D29&E29 -> S18A SAIP (F)3.2 | P29: =IFERROR(VLOOKUP(O29,'NVL Stock'!$N$1:$O$444,2,0),0) -> 12792 | Q29: =P29*1000/#REF! -> #REF! | R29: =VLOOKUP(C29,ERP!$B$1:$BM$1616,64,0) -> 20301
A30: 23 | B30: 602-040 | C30: 040120-T22W-1 | D30: =IFERROR(VLOOKUP(C30,ERP!$B$1:$AN$1548,39,0),0) -> S18A SAIP (F) | E30: =IFERROR(VLOOKUP(C30,ERP!$B$1:$AO$1548,40,0),0) -> 3.2 | F30: 16 | G30: 500000 | H30: 230000 | I30: =G30-H30 -> 270000 | J30: HƯ KẸP LIỆU | L30: 415.8 | M30: =IFERROR(MIN(VLOOKUP(C30,'[1]Shortage Analysis'!C$4:U$537,19,0),0),0) -> 0 | N30: =IFERROR(MIN(VLOOKUP(C30,'[1]Shortage Analysis'!C$4:W$537,21,0),0),0) -> 0 | O30: =D30&E30 -> S18A SAIP (F)3.2 | P30: =IFERROR(VLOOKUP(O30,'NVL Stock'!$N$1:$O$444,2,0),0) -> 12792 | Q30: =P30*1000/#REF! -> #REF! | R30: =VLOOKUP(C30,ERP!$B$1:$BM$1616,64,0) -> 20037
A31: 24 | B31: 603-052 | C31: 040200-T66H | D31: =IFERROR(VLOOKUP(C31,ERP!$B$1:$AN$1548,39,0),0) -> STS304CU WSA | E31: =IFERROR(VLOOKUP(C31,ERP!$B$1:$AO$1548,40,0),0) -> 3.2 | F31: 17 | G31: 500000 | H31: 176000 | I31: =G31-H31 -> 324000 | K31: =53000 -> 53000 | L31: 651.24 | M31: =IFERROR(MIN(VLOOKUP(C31,'[1]Shortage Analysis'!C$4:U$537,19,0),0),0) -> -565658 | N31: =IFERROR(MIN(VLOOKUP(C31,'[1]Shortage Analysis'!C$4:W$537,21,0),0),0) -> -565658 | O31: =D31&E31 -> STS304CU WSA3.2 | P31: =IFERROR(VLOOKUP(O31,'NVL Stock'!$N$1:$O$444,2,0),0) -> 1170 | Q31: =P31*1000/#REF! -> #REF! | R31: =VLOOKUP(C31,ERP!$B$1:$BM$1616,64,0) -> 40069
A32: 25 | B32: 602-045 | C32: 040140-T12W | D32: =IFERROR(VLOOKUP(C32,ERP!$B$1:$AN$1548,39,0),0) -> S18A SAIP (F) | E32: =IFERROR(VLOOKUP(C32,ERP!$B$1:$AO$1548,40,0),0) -> 3.25 | F32: 18 | G32: 1000000 | H32: 584500 | I32: =G32-H32 -> 415500 | K32: =47000+31000 -> 78000 | L32: 702.195 | M32: =IFERROR(MIN(VLOOKUP(C32,'[1]Shortage Analysis'!C$4:U$537,19,0),0),0) -> -199942.5 | N32: =IFERROR(MIN(VLOOKUP(C32,'[1]Shortage Analysis'!C$4:W$537,21,0),0),0) -> -199942.5 | O32: =D32&E32 -> S18A SAIP (F)3.25 | P32: =IFERROR(VLOOKUP(O32,'NVL Stock'!$N$1:$O$444,2,0),0) -> 7651 | Q32: =P32*1000/#REF! -> #REF! | R32: =VLOOKUP(C32,ERP!$B$1:$BM$1616,64,0) -> 20039
A33: 26 | B33: 603-021 | C33: 030045-CB2W | D33: =IFERROR(VLOOKUP(C33,ERP!$B$1:$AN$1548,39,0),0) -> S18A SAIP (F) | E33: =IFERROR(VLOOKUP(C33,ERP!$B$1:$AO$1548,40,0),0) -> 2.46 | F33: 19 | G33: 500000 | H33: 499400 | I33: =G33-H33 -> 600 | L33: 0.396 | M33: =IFERROR(MIN(VLOOKUP(C33,'[1]Shortage Analysis'!C$4:U$537,19,0),0),0) -> -55000 | N33: =IFERROR(MIN(VLOOKUP(C33,'[1]Shortage Analysis'!C$4:W$537,21,0),0),0) -> -155000 | O33: =D33&E33 -> S18A SAIP (F)2.46 | P33: =IFERROR(VLOOKUP(O33,'NVL Stock'!$N$1:$O$444,2,0),0) -> 3881 | Q33: =P33*1000/#REF! -> #REF! | R33: =VLOOKUP(C33,ERP!$B$1:$BM$1616,64,0) -> 51818
A34: 27 | B34: 602-016 | C34: 030060-C62W | D34: =IFERROR(VLOOKUP(C34,ERP!$B$1:$AN$1548,39,0),0) -> S18A SAIP (F) | E34: =IFERROR(VLOOKUP(C34,ERP!$B$1:$AO$1548,40,0),0) -> 2.46 | G34: 100000 | H34: 0 | I34: =G34-H34 -> 100000 | L34: 62 | M34: =IFERROR(MIN(VLOOKUP(C34,'[1]Shortage Analysis'!C$4:U$537,19,0),0),0) -> -38332 | N34: =IFERROR(MIN(VLOOKUP(C34,'[1]Shortage Analysis'!C$4:W$537,21,0),0),0) -> -38332 | O34: =D34&E34 -> S18A SAIP (F)2.46 | P34: =IFERROR(VLOOKUP(O34,'NVL Stock'!$N$1:$O$444,2,0),0) -> 3881 | Q34: =P34*1000/#REF! -> #REF! | R34: =VLOOKUP(C34,ERP!$B$1:$BM$1616,64,0) -> 40225
A35: 28 | B35: 604-002 | C35: 040100-PSEW-AS | D35: =IFERROR(VLOOKUP(C35,ERP!$B$1:$AN$1548,39,0),0) -> S22A SAIP (F) | E35: =IFERROR(VLOOKUP(C35,ERP!$B$1:$AO$1548,40,0),0) -> 3.55 | F35: 20 | G35: 100000 | H35: 0 | I35: =G35-H35 -> 100000 | L35: 150 | M35: =IFERROR(MIN(VLOOKUP(C35,'[1]Shortage Analysis'!C$4:U$537,19,0),0),0) -> -340599 | N35: =IFERROR(MIN(VLOOKUP(C35,'[1]Shortage Analysis'!C$4:W$537,21,0),0),0) -> -340599 | O35: =D35&E35 -> S22A SAIP (F)3.55 | P35: =IFERROR(VLOOKUP(O35,'NVL Stock'!$N$1:$O$444,2,0),0) -> 343 | Q35: =P35*1000/#REF! -> #REF! | R35: =VLOOKUP(C35,ERP!$B$1:$BM$1616,64,0) -> 50648
A36: 29 | B36: 602-035 | C36: 040100-TC2W-1 | D36: =IFERROR(VLOOKUP(C36,ERP!$B$1:$AN$1548,39,0),0) -> S18A SAIP (F) | E36: =IFERROR(VLOOKUP(C36,ERP!$B$1:$AO$1548,40,0),0) -> 3.45 | F36: 21 | G36: 600000 | H36: 283500 | I36: =G36-H36 -> 316500 | K36: =29000+57000 -> 86000 | L36: 458.925 | M36: =IFERROR(MIN(VLOOKUP(C36,'[1]Shortage Analysis'!C$4:U$537,19,0),0),0) -> -703424.46 | N36: =IFERROR(MIN(VLOOKUP(C36,'[1]Shortage Analysis'!C$4:W$537,21,0),0),0) -> -703424.46 | O36: =D36&E36 -> S18A SAIP (F)3.45 | P36: =IFERROR(VLOOKUP(O36,'NVL Stock'!$N$1:$O$444,2,0),0) -> 1513 | Q36: =P36*1000/#REF! -> #REF! | R36: =VLOOKUP(C36,ERP!$B$1:$BM$1616,64,0) -> 20023
A37: 30 | B37: 604-009 | C37: 040110-J12P-A | D37: =IFERROR(VLOOKUP(C37,ERP!$B$1:$AN$1548,39,0),0) -> S18A SAIP (F) | E37: =IFERROR(VLOOKUP(C37,ERP!$B$1:$AO$1548,40,0),0) -> 3.25 | F37: 22 | G37: 420000 | H37: 243600 | I37: =G37-H37 -> 176400 | K37: =87600 -> 87600 | L37: 224.028 | M37: =IFERROR(MIN(VLOOKUP(C37,'[1]Shortage Analysis'!C$4:U$537,19,0),0),0) -> -419999 | N37: =IFERROR(MIN(VLOOKUP(C37,'[1]Shortage Analysis'!C$4:W$537,21,0),0),0) -> -419999 | O37: =D37&E37 -> S18A SAIP (F)3.25 | P37: =IFERROR(VLOOKUP(O37,'NVL Stock'!$N$1:$O$444,2,0),0) -> 7651 | Q37: =P37*1000/#REF! -> #REF! | R37: =VLOOKUP(C37,ERP!$B$1:$BM$1616,64,0) -> 40027
A38: 31 | B38: 603-049 | C38: 040180-P62W | D38: =IFERROR(VLOOKUP(C38,ERP!$B$1:$AN$1548,39,0),0) -> S18A SAIP (F) | E38: =IFERROR(VLOOKUP(C38,ERP!$B$1:$AO$1548,40,0),0) -> 3.2 | F38: 23 | G38: 800000 | H38: 406500 | I38: =G38-H38 -> 393500 | K38: =85800 -> 85800 | L38: 629.6 | M38: =IFERROR(MIN(VLOOKUP(C38,'[1]Shortage Analysis'!C$4:U$537,19,0),0),0) -> -311542 | N38: =IFERROR(MIN(VLOOKUP(C38,'[1]Shortage Analysis'!C$4:W$537,21,0),0),0) -> -311542 | O38: =D38&E38 -> S18A SAIP (F)3.2 | P38: =IFERROR(VLOOKUP(O38,'NVL Stock'!$N$1:$O$444,2,0),0) -> 12792 | Q38: =P38*1000/#REF! -> #REF! | R38: =VLOOKUP(C38,ERP!$B$1:$BM$1616,64,0) -> 20040
A39: 32 | B39: 603-097 | C39: 040120-T22W | D39: =IFERROR(VLOOKUP(C39,ERP!$B$1:$AN$1548,39,0),0) -> S18A SAIP (F) | E39: =IFERROR(VLOOKUP(C39,ERP!$B$1:$AO$1548,40,0),0) -> 3.2 | F39: 24 | G39: 1500000 | H39: 1006500 | I39: =G39-H39 -> 493500 | K39: =64300+25000 -> 89300 | L39: 764.925 | M39: =IFERROR(MIN(VLOOKUP(C39,'[1]Shortage Analysis'!C$4:U$537,19,0),0),0) -> 0 | N39: =IFERROR(MIN(VLOOKUP(C39,'[1]Shortage Analysis'!C$4:W$537,21,0),0),0) -> 0 | O39: =D39&E39 -> S18A SAIP (F)3.2 | P39: =IFERROR(VLOOKUP(O39,'NVL Stock'!$N$1:$O$444,2,0),0) -> 12792 | Q39: =P39*1000/#REF! -> #REF! | R39: =VLOOKUP(C39,ERP!$B$1:$BM$1616,64,0) -> LGSO3
A40: 33 | B40: 603-024 | C40: 030060-PB2W-AZ | D40: =IFERROR(VLOOKUP(C40,ERP!$B$1:$AN$1548,39,0),0) -> S18A SAIP (F) | E40: =IFERROR(VLOOKUP(C40,ERP!$B$1:$AO$1548,40,0),0) -> 2.46 | F40: 25,50,53 | G40: 5000000 | H40: 1478700 | I40: =G40-H40 -> 3521300 | K40: =94000+15000+66000+95000 -> 270000 | L40: 1760.65 | M40: =IFERROR(MIN(VLOOKUP(C40,'[1]Shortage Analysis'!C$4:U$537,19,0),0),0) -> -6985000 | N40: =IFERROR(MIN(VLOOKUP(C40,'[1]Shortage Analysis'!C$4:W$537,21,0),0),0) -> -9985000 | O40: =D40&E40 -> S18A SAIP (F)2.46 | P40: =IFERROR(VLOOKUP(O40,'NVL Stock'!$N$1:$O$444,2,0),0) -> 3881 | Q40: =P40*1000/#REF! -> #REF! | R40: =VLOOKUP(C40,ERP!$B$1:$BM$1616,64,0) -> 51800
A41: 34 | B41: 603-037 | C41: 040120-T12W | D41: =IFERROR(VLOOKUP(C41,ERP!$B$1:$AN$1548,39,0),0) -> S18A SAIP (F) | E41: =IFERROR(VLOOKUP(C41,ERP!$B$1:$AO$1548,40,0),0) -> 3.25 | F41: 26,28 | G41: 4000000 | H41: 1330000 | I41: =G41-H41 -> 2670000 | K41: =89000 -> 89000 | L41: 4218.6 | M41: =IFERROR(MIN(VLOOKUP(C41,'[1]Shortage Analysis'!C$4:U$537,19,0),0),0) -> -72418.8 | N41: =IFERROR(MIN(VLOOKUP(C41,'[1]Shortage Analysis'!C$4:W$537,21,0),0),0) -> -1018224.8 | O41: =D41&E41 -> S18A SAIP (F)3.25 | P41: =IFERROR(VLOOKUP(O41,'NVL Stock'!$N$1:$O$444,2,0),0) -> 7651 | Q41: =P41*1000/#REF! -> #REF! | R41: =VLOOKUP(C41,ERP!$B$1:$BM$1616,64,0) -> 20018
...

Sheet ERP
A1: Master Code | B1: Mã s?n ph?m | C1: Tên s?n ph?m | D1: Mã s? công ty | E1: Ðánh giá | F1: Ngày dang ký | G1: Mã s? ch?nh lý | H1: Quy cách | I1: Ðon v? | J1: Ðon v? dóng gói | K1: -1 | L1: -2 | M1: -3 | N1: -4 | O1: -5 | P1: -6 | Q1: -7 | R1: -8 | S1: -9 | T1: -10 | U1: -11 | V1: -12 | W1: H/D Ðon v? tr?ng lu?ng | X1: Ðon v? tr?ng lu?ng | Y1: Quãng du?ng c?t | Z1: Chi?u dài | AA1: X? lý nhi?t | AB1: Ðon v? d? c?ng | AC1: Ð? c?ng b? m?t | AD1: Ð? c?ng lõi | AE1: X? lý b? m?t | AF1: Ð? dày chính | AG1: Ð? dày th? 2 | AH1: Lo?i gia công | AI1: Mã B?n v? quy trình | AJ1: Nguyên v?t li?u | AK1: T?n kho an toàn | AL1: Phân lo?i ph? | AM1: Ngày ph? | AN1: Ch?t li?u | AO1: Quy cách | AP1: Heading, Foaming | AQ1: Rolling, Sem`s, Tapping | AR1: Gia công, c?t t?a, c?t | AS1: X? lý nhi?t | AT1: M? | AU1: Son ph? | AV1: Ðóng gói | AW1: Hàng còn hay h?t | AX1: Ngày dang ký | BA1: Sub GdCode1 | BB1: Sub GdCode2 | BC1: Sub GdCode3 | BD1: Sub GdCode4 | BE1: Sub GdCode5 | BG1: CÔNG ĐOẠN | BH1: S/M | BI1: C/O | BJ1: M/C HD | BK1: M/C RL | BL1: M/C CT | BM1: Master code
A2: 52401 | B2: #60400-P12W | C2: PH DWS-SS (2Line) | D2: BSVN | F2: 43879 | H2: #6x40 | I2: EA | J2: 0 | K2: 6S | O2: TS1 | W2: 2.51 | X2: 2.45 | Y2: 0 | Z2: 0 | AA2: 2 | AE2: W | AI2: 60 | AJ2: 1810290 | AK2: 0 | AN2: S18A SAIP | AO2: 2.9 | AX2: 20200218 | AY2: 10[H/D],30[R/L],70[&gt;H/T],80[&gt;P/T],85[ST/ PK],99[P/K] | BG2: =IF(LEFT(AY2,2)="98","X","O") -> O | BH2: =IF(IFERROR(SEARCH("45",$AY2,1),0)>0,"Y","") | BI2: =IF(IFERROR(SEARCH("86",$AY2,1),0)>0,"Y","") | BJ2: =IF(L2="",K2,IF(M2="",K2&","&L2,IF(N2="",K2&","&L2&","&M2,K2&","&L2&","&M2&","&N2))) -> 6S | BK2: =IF(P2="",O2,IF(Q2="",O2&","&P2,IF(R2="",O2&","&P2&","&Q2,IO2&","&P2&","&Q2&","&R2))) -> TS1 | BL2: =IF(S2=0,"",S2) | BM2: =A2 -> 52401
B3: #80130-PDEZ-S | C3: PH SDS SE | D3: TBVN | F3: 43713 | H3: #8x13 | I3: EA | J3: 2000 | K3: Z | W3: 1.4 | X3: 1.49 | Y3: 0 | Z3: 0 | AA3: E | AE3: Z | AI3: 15 | AJ3: P02200325 | AK3: 0 | AL3: 0 | AN3: S22A SAIP | AO3: 0 | AX3: 20190905 | AY3: 98[PUR],70[&gt;H/T],80[&gt;P/T],85[ST/ PK],99[P/K] | BG3: =IF(LEFT(AY3,2)="98","X","O") -> X | BH3: =IF(IFERROR(SEARCH("45",$AY3,1),0)>0,"Y","") | BI3: =IF(IFERROR(SEARCH("86",$AY3,1),0)>0,"Y","") | BJ3: =IF(L3="",K3,IF(M3="",K3&","&L3,IF(N3="",K3&","&L3&","&M3,K3&","&L3&","&M3&","&N3))) -> Z | BK3: =IF(P3="",O3,IF(Q3="",O3&","&P3,IF(R3="",O3&","&P3&","&Q3,IO3&","&P3&","&Q3&","&R3))) -> 0 | BL3: =IF(S3=0,"",S3) | BM3: =A3 -> 0
B4: #80160-CD5H | C4: PH/W SDS | D4: HPW | F4: 43882 | H4: #8x16 | I4: EA | J4: 2000 | K4: Z | W4: 0 | X4: 1.53 | Y4: 0 | Z4: 0 | AA4: 7 | AE4: H | AI4: 80 | AJ4: 4100325 | AK4: 0 | AN4: STS410 WSA | AO4: 3.25 | AX4: 20200221 | AY4: 98[PUR],85[ST/ PK],99[P/K] | BG4: =IF(LEFT(AY4,2)="98","X","O") -> X | BH4: =IF(IFERROR(SEARCH("45",$AY4,1),0)>0,"Y","") | BI4: =IF(IFERROR(SEARCH("86",$AY4,1),0)>0,"Y","") | BJ4: =IF(L4="",K4,IF(M4="",K4&","&L4,IF(N4="",K4&","&L4&","&M4,K4&","&L4&","&M4&","&N4))) -> Z | BK4: =IF(P4="",O4,IF(Q4="",O4&","&P4,IF(R4="",O4&","&P4&","&Q4,IO4&","&P4&","&Q4&","&R4))) -> 0 | BL4: =IF(S4=0,"",S4) | BM4: =A4 -> 0
B5: #80160-JD5H | C5: FH SDS | D5: HPW | F5: 43882 | H5: #8x16 | I5: EA | J5: 3000 | K5: Z | W5: 0 | X5: 1.17 | Y5: 0 | Z5: 0 | AA5: 7 | AE5: H | AI5: 80 | AJ5: 4100325 | AK5: 0 | AN5: STS410 WSA | AO5: 3.25 | AX5: 20200221 | AY5: 98[PUR],85[ST/ PK],99[P/K] | BG5: =IF(LEFT(AY5,2)="98","X","O") -> X | BH5: =IF(IFERROR(SEARCH("45",$AY5,1),0)>0,"Y","") | BI5: =IF(IFERROR(SEARCH("86",$AY5,1),0)>0,"Y","") | BJ5: =IF(L5="",K5,IF(M5="",K5&","&L5,IF(N5="",K5&","&L5&","&M5,K5&","&L5&","&M5&","&N5))) -> Z | BK5: =IF(P5="",O5,IF(Q5="",O5&","&P5,IF(R5="",O5&","&P5&","&Q5,IO5&","&P5&","&Q5&","&R5))) -> 0 | BL5: =IF(S5=0,"",S5) | BM5: =A5 -> 0
B6: #80160-PDEW | C6: PH SelfDrillingScrew | D6: SEHC-R | F6: 43705 | H6: #8x16 | I6: EA | J6: 2000 | K6: Z | W6: 1.74 | X6: 1.74 | Y6: 0 | Z6: 0 | AA6: E | AE6: W | AI6: 15 | AJ6: P02200325 | AK6: 0 | AN6: S22A SAIP | AO6: 0 | AX6: 20190828 | AY6: 98[PUR],70[&gt;H/T],80[&gt;P/T],85[ST/ PK],99[P/K] | BG6: =IF(LEFT(AY6,2)="98","X","O") -> X | BH6: =IF(IFERROR(SEARCH("45",$AY6,1),0)>0,"Y","") | BI6: =IF(IFERROR(SEARCH("86",$AY6,1),0)>0,"Y","") | BJ6: =IF(L6="",K6,IF(M6="",K6&","&L6,IF(N6="",K6&","&L6&","&M6,K6&","&L6&","&M6&","&N6))) -> Z | BK6: =IF(P6="",O6,IF(Q6="",O6&","&P6,IF(R6="",O6&","&P6&","&Q6,IO6&","&P6&","&Q6&","&R6))) -> 0 | BL6: =IF(S6=0,"",S6) | BM6: =A6 -> 0
B7: #80160-PSEW | C7: PH ???? | D7: JGPP | F7: 42929 | H7: #8 x 16 | I7: EA | J7: 2000 | K7: Z | W7: 0 | X7: 1.73 | Y7: 0 | Z7: 0 | AA7: 2 | AE7: W | AI7: 15 | AJ7: P11810000 | AK7: 0 | AN7: S18A SAIP | AO7: 0 | AV7: 46023 | AX7: 20170713 | AY7: 98[PUR],70[&gt;H/T],80[&gt;P/T],85[ST/ PK],99[P/K] | BG7: =IF(LEFT(AY7,2)="98","X","O") -> X | BH7: =IF(IFERROR(SEARCH("45",$AY7,1),0)>0,"Y","") | BI7: =IF(IFERROR(SEARCH("86",$AY7,1),0)>0,"Y","") | BJ7: =IF(L7="",K7,IF(M7="",K7&","&L7,IF(N7="",K7&","&L7&","&M7,K7&","&L7&","&M7&","&N7))) -> Z | BK7: =IF(P7="",O7,IF(Q7="",O7&","&P7,IF(R7="",O7&","&P7&","&Q7,IO7&","&P7&","&Q7&","&R7))) -> 0 | BL7: =IF(S7=0,"",S7) | BM7: =A7 -> 0
A8: 99005 | B8: #80180-F12Z-5P | C8: FL + T/S-1 PVC/W | D8: HSBK | F8: 43393 | H8: #8 x18 | I8: EA | J8: 1000 | K8: M4 | O8: TS1 | W8: 2.15 | X8: 2.18 | Y8: 0 | Z8: 0 | AA8: 2 | AE8: Z | AI8: 74 | AJ8: 1850330 | AK8: 0 | AN8: S18A SAIP (F) | AO8: 3.3 | AV8: 46024 | AX8: 20181020 | AY8: 10[H/D],30[R/L],70[&gt;H/T],80[&gt;P/T],84[&gt;A/B],85[ST/ PK],99[P/K] | AZ8: 038100-1050-5F | BG8: =IF(LEFT(AY8,2)="98","X","O") -> O | BH8: =IF(IFERROR(SEARCH("45",$AY8,1),0)>0,"Y","") | BI8: =IF(IFERROR(SEARCH("86",$AY8,1),0)>0,"Y","") | BJ8: =IF(L8="",K8,IF(M8="",K8&","&L8,IF(N8="",K8&","&L8&","&M8,K8&","&L8&","&M8&","&N8))) -> M4 | BK8: =IF(P8="",O8,IF(Q8="",O8&","&P8,IF(R8="",O8&","&P8&","&Q8,IO8&","&P8&","&Q8&","&R8))) -> TS1 | BL8: =IF(S8=0,"",S8) | BM8: =A8 -> 99005
B9: 0 | C9: Bolt test ERP | D9: PONA | F9: 44345 | J9: 0 | K9: 9B | O9: M4 | W9: 1 | X9: 1.1 | Y9: 0 | Z9: 0 | AI9: 199 | AJ9: P0000 | AK9: 0 | AN9: 0 | AO9: 0 | AX9: 20210529 | AY9: 10[H/D],45[S/R],85[ST/ PK],99[P/K] | BG9: =IF(LEFT(AY9,2)="98","X","O") -> O | BH9: =IF(IFERROR(SEARCH("45",$AY9,1),0)>0,"Y","") -> Y | BI9: =IF(IFERROR(SEARCH("86",$AY9,1),0)>0,"Y","") | BJ9: =IF(L9="",K9,IF(M9="",K9&","&L9,IF(N9="",K9&","&L9&","&M9,K9&","&L9&","&M9&","&N9))) -> 9B | BK9: =IF(P9="",O9,IF(Q9="",O9&","&P9,IF(R9="",O9&","&P9&","&Q9,IO9&","&P9&","&Q9&","&R9))) -> M4 | BL9: =IF(S9=0,"",S9) | BM9: =A9 -> 0
A10: 40210 | B10: 020030-YB2B | C10: FLATNESS TTS-B | D10: SHARP | F10: 45000 | H10: 2*3 | I10: EA | J10: 50000 | K10: M3 | O10: M3 | W10: 0.13 | X10: 0.11 | Y10: 0 | Z10: 0 | AA10: 2 | AE10: B | AI10: 80 | AJ10: 1850169 | AK10: 0 | AN10: S18A SAIP (F) | AO10: 1.69 | AX10: 20230315 | AY10: 98[PUR],85[ST/ PK],99[P/K] | BG10: =IF(LEFT(AY10,2)="98","X","O") -> X | BH10: =IF(IFERROR(SEARCH("45",$AY10,1),0)>0,"Y","") | BI10: =IF(IFERROR(SEARCH("86",$AY10,1),0)>0,"Y","") | BJ10: =IF(L10="",K10,IF(M10="",K10&","&L10,IF(N10="",K10&","&L10&","&M10,K10&","&L10&","&M10&","&N10))) -> M3 | BK10: =IF(P10="",O10,IF(Q10="",O10&","&P10,IF(R10="",O10&","&P10&","&Q10,IO10&","&P10&","&Q10&","&R10))) -> M3 | BL10: =IF(S10=0,"",S10) | BM10: =A10 -> 40210
A11: 55019 | B11: 020050-P51K | C11: PH(ISO 7045) M/S(6g) | D11: FRIW | F11: 45493 | H11: M2x5 | I11: EA | J11: 0 | K11: M3 | O11: M3 | W11: 0.19 | X11: 0.19 | Y11: 0 | Z11: 0 | AA11: 0 | AE11: K | AI11: 57 | AJ11: 1000169 | AK11: 0 | AL11: 0 | AN11: S10A HD | AO11: 1.69 | AX11: 20240720 | AY11: 10[H/D],30[R/L],80[&gt;P/T],85[ST/ PK],99[P/K] | BG11: =IF(LEFT(AY11,2)="98","X","O") -> O | BH11: =IF(IFERROR(SEARCH("45",$AY11,1),0)>0,"Y","") | BI11: =IF(IFERROR(SEARCH("86",$AY11,1),0)>0,"Y","") | BJ11: =IF(L11="",K11,IF(M11="",K11&","&L11,IF(N11="",K11&","&L11&","&M11,K11&","&L11&","&M11&","&N11))) -> M3 | BK11: =IF(P11="",O11,IF(Q11="",O11&","&P11,IF(R11="",O11&","&P11&","&Q11,IO11&","&P11&","&Q11&","&R11))) -> M3 | BL11: =IF(S11=0,"",S11) | BM11: =A11 -> 55019
B12: 020050-P56H | C12: PH M/S (SUS304) | D12: SCON | F12: 43343 | H12: M2*5 | I12: EA | J12: 20000 | K12: Z | W12: 0 | X12: 0.17 | Y12: 0 | Z12: 0 | AA12: 0 | AE12: H | AI12: 80 | AJ12: 3040160 | AK12: 0 | AL12: 0 | AN12: STS304CU WSA | AO12: 1.6 | AV12: 46025 | AX12: 20180831 | AY12: 98[PUR],85[ST/ PK],99[P/K] | BG12: =IF(LEFT(AY12,2)="98","X","O") -> X | BH12: =IF(IFERROR(SEARCH("45",$AY12,1),0)>0,"Y","") | BI12: =IF(IFERROR(SEARCH("86",$AY12,1),0)>0,"Y","") | BJ12: =IF(L12="",K12,IF(M12="",K12&","&L12,IF(N12="",K12&","&L12&","&M12,K12&","&L12&","&M12&","&N12))) -> Z | BK12: =IF(P12="",O12,IF(Q12="",O12&","&P12,IF(R12="",O12&","&P12&","&Q12,IO12&","&P12&","&Q12&","&R12))) -> 0 | BL12: =IF(S12=0,"",S12) | BM12: =A12 -> 0
A13: 40207 | B13: 020060-B62W | C13: BH T/S-2(NO CUTTING) | D13: SHARP | F13: 43992 | H13: 2x6 | I13: EA | J13: 5000 | K13: M3 | O13: M3 | W13: 0.2 | X13: 0.2 | Y13: 0 | Z13: 0 | AA13: 2 | AE13: W | AI13: 60 | AJ13: 1850171 | AK13: 0 | AN13: S18A SAIP (F) | AO13: 1.71 | AX13: 20200610 | AY13: 10[H/D],30[R/L],70[&gt;H/T],80[&gt;P/T],85[ST/ PK],99[P/K] | BG13: =IF(LEFT(AY13,2)="98","X","O") -> O | BH13: =IF(IFERROR(SEARCH("45",$AY13,1),0)>0,"Y","") | BI13: =IF(IFERROR(SEARCH("86",$AY13,1),0)>0,"Y","") | BJ13: =IF(L13="",K13,IF(M13="",K13&","&L13,IF(N13="",K13&","&L13&","&M13,K13&","&L13&","&M13&","&N13))) -> M3 | BK13: =IF(P13="",O13,IF(Q13="",O13&","&P13,IF(R13="",O13&","&P13&","&Q13,IO13&","&P13&","&Q13&","&R13))) -> M3 | BL13: =IF(S13=0,"",S13) | BM13: =A13 -> 40207
A14: 40208 | B14: 020060-PB2W | C14: PH TTS-B | D14: SHARP | F14: 45359 | H14: 2x6 | I14: EA | J14: 5000 | K14: M3 | O14: M3 | W14: 0.15 | X14: 0.15 | Y14: 0 | Z14: 0 | AA14: 2 | AE14: W | AI14: 60 | AJ14: 1850169 | AK14: 0 | AL14: 0 | AN14: S18A SAIP (F) | AO14: 1.69 | AX14: 20240308 | AY14: 10[H/D],30[R/L],70[&gt;H/T],80[&gt;P/T],85[ST/ PK],99[P/K] | BG14: =IF(LEFT(AY14,2)="98","X","O") -> O | BH14: =IF(IFERROR(SEARCH("45",$AY14,1),0)>0,"Y","") | BI14: =IF(IFERROR(SEARCH("86",$AY14,1),0)>0,"Y","") | BJ14: =IF(L14="",K14,IF(M14="",K14&","&L14,IF(N14="",K14&","&L14&","&M14,K14&","&L14&","&M14&","&N14))) -> M3 | BK14: =IF(P14="",O14,IF(Q14="",O14&","&P14,IF(R14="",O14&","&P14&","&Q14,IO14&","&P14&","&Q14&","&R14))) -> M3 | BL14: =IF(S14=0,"",S14) | BM14: =A14 -> 40208
A15: 51807 | B15: 020075-PP2B | C15: PH TTS-P | D15: NAMI | F15: 43880 | H15: 2x7.5 | I15: EA | J15: 20000 | K15: M3 | O15: M3 | W15: 0.16 | X15: 0.17 | Y15: 0 | Z15: 0 | AA15: 2 | AE15: B | AI15: 60 | AJ15: 1850165 | AK15: 0 | AN15: S18A SAIP (F) | AO15: 1.65 | AX15: 20200219 | AY15: 10[H/D],30[R/L],70[&gt;H/T],80[&gt;P/T],85[ST/ PK],99[P/K] | BG15: =IF(LEFT(AY15,2)="98","X","O") -> O | BH15: =IF(IFERROR(SEARCH("45",$AY15,1),0)>0,"Y","") | BI15: =IF(IFERROR(SEARCH("86",$AY15,1),0)>0,"Y","") | BJ15: =IF(L15="",K15,IF(M15="",K15&","&L15,IF(N15="",K15&","&L15&","&M15,K15&","&L15&","&M15&","&N15))) -> M3 | BK15: =IF(P15="",O15,IF(Q15="",O15&","&P15,IF(R15="",O15&","&P15&","&Q15,IO15&","&P15&","&Q15&","&R15))) -> M3 | BL15: =IF(S15=0,"",S15) | BM15: =A15 -> 51807
A16: 20066 | B16: 020130-Z06H | C16: SHAFT HINGE | D16: SEHC | F16: 44050 | H16: 2x13 | I16: EA | J16: 5000 | K16: M3 | W16: 0.32 | X16: 0.35 | Y16: 0 | Z16: 0 | AA16: 0 | AE16: H | AI16: 86 | AJ16: 3330020 | AK16: 0 | AN16: STS304J3S WSB | AO16: 2 | AX16: 20200807 | AY16: 10[H/D],68[&gt;BF/PT],85[ST/ PK],99[P/K] | BG16: =IF(LEFT(AY16,2)="98","X","O") -> O | BH16: =IF(IFERROR(SEARCH("45",$AY16,1),0)>0,"Y","") | BI16: =IF(IFERROR(SEARCH("86",$AY16,1),0)>0,"Y","") | BJ16: =IF(L16="",K16,IF(M16="",K16&","&L16,IF(N16="",K16&","&L16&","&M16,K16&","&L16&","&M16&","&N16))) -> M3 | BK16: =IF(P16="",O16,IF(Q16="",O16&","&P16,IF(R16="",O16&","&P16&","&Q16,IO16&","&P16&","&Q16&","&R16))) -> 0 | BL16: =IF(S16=0,"",S16) | BM16: =A16 -> 20066
A17: 51830 | B17: 020170-P51W | C17: PH M/S | D17: NAMI | F17: 44567 | H17: 2x17 | I17: EA | J17: 10000 | K17: M3 | O17: M3 | W17: 0.35 | X17: 0.36 | Y17: 0 | Z17: 0 | AA17: 0 | AE17: W | AI17: 57 | AJ17: 1000169 | AK17: 0 | AN17: S10A HD | AO17: 1.69 | AX17: 20220106 | AY17: 10[H/D],30[R/L],80[&gt;P/T],85[ST/ PK],99[P/K] | BG17: =IF(LEFT(AY17,2)="98","X","O") -> O | BH17: =IF(IFERROR(SEARCH("45",$AY17,1),0)>0,"Y","") | BI17: =IF(IFERROR(SEARCH("86",$AY17,1),0)>0,"Y","") | BJ17: =IF(L17="",K17,IF(M17="",K17&","&L17,IF(N17="",K17&","&L17&","&M17,K17&","&L17&","&M17&","&N17))) -> M3 | BK17: =IF(P17="",O17,IF(Q17="",O17&","&P17,IF(R17="",O17&","&P17&","&Q17,IO17&","&P17&","&Q17&","&R17))) -> M3 | BL17: =IF(S17=0,"",S17) | BM17: =A17 -> 51830
B18: 025051-0780-3 | C18: SPRING WASHER | D18: HSV | F18: 45007 | H18: 2.5*5.1*0.7T | I18: EA | J18: 0 | W18: 0 | X18: 0 | Y18: 0 | Z18: 0 | AA18: 0 | AE18: 0 | AI18: 84 | AJ18: P15400001 | AK18: 0 | AL18: 0 | AN18: S/W SWCH62 | AO18: 0.7T | AX18: 20230322 | AY18: 98[PUR],45[S/R] | BG18: =IF(LEFT(AY18,2)="98","X","O") -> X | BH18: =IF(IFERROR(SEARCH("45",$AY18,1),0)>0,"Y","") -> Y | BI18: =IF(IFERROR(SEARCH("86",$AY18,1),0)>0,"Y","") | BJ18: =IF(L18="",K18,IF(M18="",K18&","&L18,IF(N18="",K18&","&L18&","&M18,K18&","&L18&","&M18&","&N18))) -> 0 | BK18: =IF(P18="",O18,IF(Q18="",O18&","&P18,IF(R18="",O18&","&P18&","&Q18,IO18&","&P18&","&Q18&","&R18))) -> 0 | BL18: =IF(S18=0,"",S18) | BM18: =A18 -> 0
B19: 026080-0500-2F | C19: PLAIN WASHER | D19: HSV | F19: 44288 | H19: 2.6x8.0x0.5T | I19: EA | J19: 0 | K19: Z | W19: 0.18 | X19: 0.18 | Y19: 0 | Z19: 0 | AA19: 0 | AB19: 0 | AE19: 0 | AI19: 84 | AJ19: P15500001 | AK19: 0 | AL19: 0 | AN19: P/W SPCC | AO19: 0.5T | AX19: 20210402 | AY19: 98[PUR],45[S/R] | BG19: =IF(LEFT(AY19,2)="98","X","O") -> X | BH19: =IF(IFERROR(SEARCH("45",$AY19,1),0)>0,"Y","") -> Y | BI19: =IF(IFERROR(SEARCH("86",$AY19,1),0)>0,"Y","") | BJ19: =IF(L19="",K19,IF(M19="",K19&","&L19,IF(N19="",K19&","&L19&","&M19,K19&","&L19&","&M19&","&N19))) -> Z | BK19: =IF(P19="",O19,IF(Q19="",O19&","&P19,IF(R19="",O19&","&P19&","&Q19,IO19&","&P19&","&Q19&","&R19))) -> 0 | BL19: =IF(S19=0,"",S19) | BM19: =A19 -> 0
B20: 027055-0780-3 | C20: SPRING WASHER | D20: HSV | F20: 44288 | H20: 2.7x5.5x0.7T | I20: EA | J20: 0 | K20: Z | W20: 0.08 | X20: 0.08 | Y20: 0 | Z20: 0 | AA20: 0 | AE20: 0 | AI20: 84 | AJ20: P15400001 | AK20: 0 | AL20: 0 | AN20: S/W SWCH62 | AO20: 0.7T | AX20: 20210402 | AY20: 98[PUR],45[S/R] | BG20: =IF(LEFT(AY20,2)="98","X","O") -> X | BH20: =IF(IFERROR(SEARCH("45",$AY20,1),0)>0,"Y","") -> Y | BI20: =IF(IFERROR(SEARCH("86",$AY20,1),0)>0,"Y","") | BJ20: =IF(L20="",K20,IF(M20="",K20&","&L20,IF(N20="",K20&","&L20&","&M20,K20&","&L20&","&M20&","&N20))) -> Z | BK20: =IF(P20="",O20,IF(Q20="",O20&","&P20,IF(R20="",O20&","&P20&","&Q20,IO20&","&P20&","&Q20&","&R20))) -> 0 | BL20: =IF(S20=0,"",S20) | BM20: =A20 -> 0
B21: 027060-0600-2F | C21: PLAIN WASHER | D21: HSV | F21: 44288 | H21: 2.7x6.0x0.6T | J21: 0 | K21: Z | W21: 0.07 | X21: 0.07 | Y21: 0 | Z21: 0 | AA21: 0 | AE21: 0 | AI21: 84 | AJ21: P15500002 | AK21: 0 | AN21: P/W SPCC | AO21: 0.6T | AX21: 20210402 | AY21: 98[PUR],45[S/R] | BG21: =IF(LEFT(AY21,2)="98","X","O") -> X | BH21: =IF(IFERROR(SEARCH("45",$AY21,1),0)>0,"Y","") -> Y | BI21: =IF(IFERROR(SEARCH("86",$AY21,1),0)>0,"Y","") | BJ21: =IF(L21="",K21,IF(M21="",K21&","&L21,IF(N21="",K21&","&L21&","&M21,K21&","&L21&","&M21&","&N21))) -> Z | BK21: =IF(P21="",O21,IF(Q21="",O21&","&P21,IF(R21="",O21&","&P21&","&Q21,IO21&","&P21&","&Q21&","&R21))) -> 0 | BL21: =IF(S21=0,"",S21) | BM21: =A21 -> 0
A22: 52102 | B22: 030030-P51N | C22: PH M/S | D22: HANM | F22: 43774 | H22: 3x3 | I22: EA | J22: 0 | K22: M3 | O22: M3 | W22: 0.35 | X22: 0.38 | Y22: 0 | Z22: 0 | AA22: 0 | AE22: N | AI22: 57 | AJ22: 1000260 | AK22: 0 | AL22: 0 | AN22: S10A HD | AO22: 2.6 | AX22: 20191105 | AY22: 10[H/D],30[R/L],80[&gt;P/T],85[ST/ PK],99[P/K] | BG22: =IF(LEFT(AY22,2)="98","X","O") -> O | BH22: =IF(IFERROR(SEARCH("45",$AY22,1),0)>0,"Y","") | BI22: =IF(IFERROR(SEARCH("86",$AY22,1),0)>0,"Y","") | BJ22: =IF(L22="",K22,IF(M22="",K22&","&L22,IF(N22="",K22&","&L22&","&M22,K22&","&L22&","&M22&","&N22))) -> M3 | BK22: =IF(P22="",O22,IF(Q22="",O22&","&P22,IF(R22="",O22&","&P22&","&Q22,IO22&","&P22&","&Q22&","&R22))) -> M3 | BL22: =IF(S22=0,"",S22) | BM22: =A22 -> 52102
A23: 50314 | B23: 030030-Z54B-H | C23: LOWHEADBOLTSOCKET M3 | D23: BRSG | F23: 44930 | H23: M3*3 | I23: EA | J23: 10000 | K23: M3 | O23: M3 | W23: 0.38 | X23: 0.36 | Y23: 0 | Z23: 0 | AA23: 303 | AE23: B | AI23: 60 | AJ23: 4350260 | AK23: 0 | AL23: 0 | AN23: SCM435 PASAIP | AO23: 2.6 | AX23: 20230104 | AY23: 10[H/D],30[R/L],70[&gt;H/T],80[&gt;P/T],85[ST/ PK],99[P/K] | BG23: =IF(LEFT(AY23,2)="98","X","O") -> O | BH23: =IF(IFERROR(SEARCH("45",$AY23,1),0)>0,"Y","") | BI23: =IF(IFERROR(SEARCH("86",$AY23,1),0)>0,"Y","") | BJ23: =IF(L23="",K23,IF(M23="",K23&","&L23,IF(N23="",K23&","&L23&","&M23,K23&","&L23&","&M23&","&N23))) -> M3 | BK23: =IF(P23="",O23,IF(Q23="",O23&","&P23,IF(R23="",O23&","&P23&","&Q23,IO23&","&P23&","&Q23&","&R23))) -> M3 | BL23: =IF(S23=0,"",S23) | BM23: =A23 -> 50314
A24: 52105 | B24: 030040-B51N-S | C24: BH M/S SE | D24: HANM | F24: 43775 | H24: 3x4 | I24: EA | J24: 5000 | K24: M3 | O24: M3 | W24: 0.45 | X24: 0.45 | Y24: 0 | Z24: 0 | AA24: 0 | AE24: N | AI24: 57 | AJ24: 1000260 | AK24: 0 | AL24: 0 | AN24: S10A HD | AO24: 2.6 | AX24: 20191106 | AY24: 10[H/D],30[R/L],80[&gt;P/T],85[ST/ PK],99[P/K] | BG24: =IF(LEFT(AY24,2)="98","X","O") -> O | BH24: =IF(IFERROR(SEARCH("45",$AY24,1),0)>0,"Y","") | BI24: =IF(IFERROR(SEARCH("86",$AY24,1),0)>0,"Y","") | BJ24: =IF(L24="",K24,IF(M24="",K24&","&L24,IF(N24="",K24&","&L24&","&M24,K24&","&L24&","&M24&","&N24))) -> M3 | BK24: =IF(P24="",O24,IF(Q24="",O24&","&P24,IF(R24="",O24&","&P24&","&Q24,IO24&","&P24&","&Q24&","&R24))) -> M3 | BL24: =IF(S24=0,"",S24) | BM24: =A24 -> 52105
A25: 52103 | B25: 030040-C51N | C25: PH/W M/S | D25: HANM | F25: 43775 | H25: 3x4 | I25: EA | J25: 5000 | K25: M3 | O25: M3 | W25: 0.54 | X25: 0.54 | Y25: 0 | Z25: 0 | AA25: 0 | AE25: N | AI25: 57 | AJ25: 1000260 | AK25: 0 | AL25: 0 | AN25: S10A HD | AO25: 2.6 | AX25: 20191106 | AY25: 10[H/D],30[R/L],80[&gt;P/T],85[ST/ PK],99[P/K] | BG25: =IF(LEFT(AY25,2)="98","X","O") -> O | BH25: =IF(IFERROR(SEARCH("45",$AY25,1),0)>0,"Y","") | BI25: =IF(IFERROR(SEARCH("86",$AY25,1),0)>0,"Y","") | BJ25: =IF(L25="",K25,IF(M25="",K25&","&L25,IF(N25="",K25&","&L25&","&M25,K25&","&L25&","&M25&","&N25))) -> M3 | BK25: =IF(P25="",O25,IF(Q25="",O25&","&P25,IF(R25="",O25&","&P25&","&Q25,IO25&","&P25&","&Q25&","&R25))) -> M3 | BL25: =IF(S25=0,"",S25) | BM25: =A25 -> 52103
A26: 52104 | B26: 030040-P51N | C26: PH M/S | D26: HANM | F26: 43774 | H26: 3x4 | I26: EA | J26: 5000 | K26: M3 | O26: M3 | W26: 0.41 | X26: 0.4 | Y26: 0 | Z26: 0 | AA26: 0 | AE26: N | AI26: 57 | AJ26: 1000260 | AK26: 0 | AL26: 0 | AN26: S10A HD | AO26: 2.6 | AX26: 20191105 | AY26: 10[H/D],30[R/L],80[&gt;P/T],85[ST/ PK],99[P/K] | BG26: =IF(LEFT(AY26,2)="98","X","O") -> O | BH26: =IF(IFERROR(SEARCH("45",$AY26,1),0)>0,"Y","") | BI26: =IF(IFERROR(SEARCH("86",$AY26,1),0)>0,"Y","") | BJ26: =IF(L26="",K26,IF(M26="",K26&","&L26,IF(N26="",K26&","&L26&","&M26,K26&","&L26&","&M26&","&N26))) -> M3 | BK26: =IF(P26="",O26,IF(Q26="",O26&","&P26,IF(R26="",O26&","&P26&","&Q26,IO26&","&P26&","&Q26&","&R26))) -> M3 | BL26: =IF(S26=0,"",S26) | BM26: =A26 -> 52104
A27: 51812 | B27: 030045-B62B | C27: BH T/S-2(NO CUTTING) | D27: NAMI | F27: 44014 | H27: 3x4.5 | I27: EA | J27: 0 | K27: M3 | O27: M3 | W27: 0.49 | X27: 0.51 | Y27: 0 | Z27: 0 | AA27: 2 | AE27: B | AI27: 60 | AJ27: 1850246 | AK27: 0 | AN27: S18A SAIP (F) | AO27: 2.46 | AX27: 20200702 | AY27: 10[H/D],30[R/L],70[&gt;H/T],80[&gt;P/T],85[ST/ PK],99[P/K] | BG27: =IF(LEFT(AY27,2)="98","X","O") -> O | BH27: =IF(IFERROR(SEARCH("45",$AY27,1),0)>0,"Y","") | BI27: =IF(IFERROR(SEARCH("86",$AY27,1),0)>0,"Y","") | BJ27: =IF(L27="",K27,IF(M27="",K27&","&L27,IF(N27="",K27&","&L27&","&M27,K27&","&L27&","&M27&","&N27))) -> M3 | BK27: =IF(P27="",O27,IF(Q27="",O27&","&P27,IF(R27="",O27&","&P27&","&Q27,IO27&","&P27&","&Q27&","&R27))) -> M3 | BL27: =IF(S27=0,"",S27) | BM27: =A27 -> 51812
A28: 51802 | B28: 030045-B62W-Z | C28: BH T/S-2(NO CUTTING) | D28: NAMI | F28: 43819 | H28: 3x4.5 | I28: EA | J28: 20000 | K28: M3 | O28: M3 | W28: 0.49 | X28: 0.45 | Y28: 0 | Z28: 0 | AA28: 2 | AE28: W | AI28: 60 | AJ28: 1850246 | AK28: 0 | AL28: 0 | AN28: S18A SAIP (F) | AO28: 2.46 | AX28: 20191220 | AY28: 10[H/D],30[R/L],70[&gt;H/T],80[&gt;P/T],85[ST/ PK],99[P/K] | BG28: =IF(LEFT(AY28,2)="98","X","O") -> O | BH28: =IF(IFERROR(SEARCH("45",$AY28,1),0)>0,"Y","") | BI28: =IF(IFERROR(SEARCH("86",$AY28,1),0)>0,"Y","") | BJ28: =IF(L28="",K28,IF(M28="",K28&","&L28,IF(N28="",K28&","&L28&","&M28,K28&","&L28&","&M28&","&N28))) -> M3 | BK28: =IF(P28="",O28,IF(Q28="",O28&","&P28,IF(R28="",O28&","&P28&","&Q28,IO28&","&P28&","&Q28&","&R28))) -> M3 | BL28: =IF(S28=0,"",S28) | BM28: =A28 -> 51802
A29: 51831 | B29: 030045-CB2B | C29: PH/W TTS-B | D29: NAMI | F29: 44551 | H29: 3x4.5 | I29: EA | J29: 10000 | K29: M4 | O29: M3 | W29: 0.66 | X29: 0.69 | Y29: 0 | Z29: 0 | AA29: 2 | AE29: B | AI29: 60 | AJ29: 1850246 | AK29: 0 | AL29: 0 | AN29: S18A SAIP (F) | AO29: 2.46 | AX29: 20211221 | AY29: 10[H/D],30[R/L],70[&gt;H/T],80[&gt;P/T],85[ST/ PK],99[P/K] | BG29: =IF(LEFT(AY29,2)="98","X","O") -> O | BH29: =IF(IFERROR(SEARCH("45",$AY29,1),0)>0,"Y","") | BI29: =IF(IFERROR(SEARCH("86",$AY29,1),0)>0,"Y","") | BJ29: =IF(L29="",K29,IF(M29="",K29&","&L29,IF(N29="",K29&","&L29&","&M29,K29&","&L29&","&M29&","&N29))) -> M4 | BK29: =IF(P29="",O29,IF(Q29="",O29&","&P29,IF(R29="",O29&","&P29&","&Q29,IO29&","&P29&","&Q29&","&R29))) -> M3 | BL29: =IF(S29=0,"",S29) | BM29: =A29 -> 51831
A30: 51818 | B30: 030045-CB2W | C30: PH/W TTS-B | D30: NAMI | F30: 43965 | H30: 3x4.5 | I30: EA | J30: 20000 | K30: M4 | O30: M3 | W30: 0.66 | X30: 0.67 | Y30: 0 | Z30: 0 | AA30: 2 | AE30: W | AI30: 60 | AJ30: 1850246 | AK30: 0 | AL30: 0 | AN30: S18A SAIP (F) | AO30: 2.46 | AX30: 20200514 | AY30: 10[H/D],30[R/L],70[&gt;H/T],80[&gt;P/T],85[ST/ PK],99[P/K] | BG30: =IF(LEFT(AY30,2)="98","X","O") -> O | BH30: =IF(IFERROR(SEARCH("45",$AY30,1),0)>0,"Y","") | BI30: =IF(IFERROR(SEARCH("86",$AY30,1),0)>0,"Y","") | BJ30: =IF(L30="",K30,IF(M30="",K30&","&L30,IF(N30="",K30&","&L30&","&M30,K30&","&L30&","&M30&","&N30))) -> M4 | BK30: =IF(P30="",O30,IF(Q30="",O30&","&P30,IF(R30="",O30&","&P30&","&Q30,IO30&","&P30&","&Q30&","&R30))) -> M3 | BL30: =IF(S30=0,"",S30) | BM30: =A30 -> 51818
A31: 51810 | B31: 030046-B62W | C31: BH T/S-2(NO CUTTING) | D31: NAMI | F31: 43960 | H31: 3x4.6 | I31: EA | J31: 20000 | K31: M3 | O31: M3 | W31: 0.5 | X31: 0.55 | Y31: 0 | Z31: 0 | AA31: 2 | AE31: W | AI31: 60 | AJ31: 1850246 | AK31: 0 | AN31: S18A SAIP (F) | AO31: 2.46 | AX31: 20200509 | AY31: 10[H/D],30[R/L],70[&gt;H/T],80[&gt;P/T],85[ST/ PK],99[P/K] | BG31: =IF(LEFT(AY31,2)="98","X","O") -> O | BH31: =IF(IFERROR(SEARCH("45",$AY31,1),0)>0,"Y","") | BI31: =IF(IFERROR(SEARCH("86",$AY31,1),0)>0,"Y","") | BJ31: =IF(L31="",K31,IF(M31="",K31&","&L31,IF(N31="",K31&","&L31&","&M31,K31&","&L31&","&M31&","&N31))) -> M3 | BK31: =IF(P31="",O31,IF(Q31="",O31&","&P31,IF(R31="",O31&","&P31&","&Q31,IO31&","&P31&","&Q31&","&R31))) -> M3 | BL31: =IF(S31=0,"",S31) | BM31: =A31 -> 51810
A32: 50301 | B32: 030050-P51W-4 | C32: PH M/S S,P/W | D32: BISG | F32: 43879 | H32: 3x5 | I32: EA | J32: 5000 | K32: M3 | O32: S6 | W32: 0.43 | X32: 0.68 | Y32: 0 | Z32: 0 | AA32: 0 | AE32: W | AI32: 18 | AJ32: 1000260 | AK32: 0 | AN32: S10A HD | AO32: 2.6 | AQ32: X? lông d?n - cán ren | AX32: 20200218 | AY32: 10[H/D],45[S/R],80[&gt;P/T],85[ST/ PK],99[P/K] | AZ32: 026080-0500-2F | BA32: 027055-0780-3 | BG32: =IF(LEFT(AY32,2)="98","X","O") -> O | BH32: =IF(IFERROR(SEARCH("45",$AY32,1),0)>0,"Y","") -> Y | BI32: =IF(IFERROR(SEARCH("86",$AY32,1),0)>0,"Y","") | BJ32: =IF(L32="",K32,IF(M32="",K32&","&L32,IF(N32="",K32&","&L32&","&M32,K32&","&L32&","&M32&","&N32))) -> M3 | BK32: =IF(P32="",O32,IF(Q32="",O32&","&P32,IF(R32="",O32&","&P32&","&Q32,IO32&","&P32&","&Q32&","&R32))) -> S6 | BL32: =IF(S32=0,"",S32) | BM32: =A32 -> 50301
A33: 33003 | B33: 030050-P51Z | C33: PH M/S | D33: SCON | F33: 43512 | H33: 3*5 | I33: EA | J33: 0 | K33: M3 | O33: M3 | W33: 0.45 | X33: 0.45 | Y33: 0 | Z33: 0 | AA33: 0 | AE33: Z | AI33: 57 | AJ33: 1000260 | AK33: 0 | AN33: S10A HD | AO33: 2.6 | AX33: 20190216 | AY33: 10[H/D],30[R/L],80[&gt;P/T],85[ST/ PK],99[P/K] | BG33: =IF(LEFT(AY33,2)="98","X","O") -> O | BH33: =IF(IFERROR(SEARCH("45",$AY33,1),0)>0,"Y","") | BI33: =IF(IFERROR(SEARCH("86",$AY33,1),0)>0,"Y","") | BJ33: =IF(L33="",K33,IF(M33="",K33&","&L33,IF(N33="",K33&","&L33&","&M33,K33&","&L33&","&M33&","&N33))) -> M3 | BK33: =IF(P33="",O33,IF(Q33="",O33&","&P33,IF(R33="",O33&","&P33&","&Q33,IO33&","&P33&","&Q33&","&R33))) -> M3 | BL33: =IF(S33=0,"",S33) | BM33: =A33 -> 33003
A34: 20089 | B34: 030050-P52W-3N | C34: PH M/S S/W | D34: SEHC | F34: 45324 | H34: M3x5 | I34: EA | J34: 6000 | K34: M3 | O34: M3 | W34: 0.43 | X34: 0.53 | Y34: 0 | Z34: 0 | AA34: 0 | AE34: W | AI34: 18 | AJ34: 1850260 | AK34: 0 | AL34: 0 | AN34: S18A SAIP (F) | AO34: 2.6 | AX34: 20240202 | AY34: 10[H/D],45[S/R],80[&gt;P/T],85[ST/ PK],99[P/K] | AZ34: 027055-0780-3 | BG34: =IF(LEFT(AY34,2)="98","X","O") -> O | BH34: =IF(IFERROR(SEARCH("45",$AY34,1),0)>0,"Y","") -> Y | BI34: =IF(IFERROR(SEARCH("86",$AY34,1),0)>0,"Y","") | BJ34: =IF(L34="",K34,IF(M34="",K34&","&L34,IF(N34="",K34&","&L34&","&M34,K34&","&L34&","&M34&","&N34))) -> M3 | BK34: =IF(P34="",O34,IF(Q34="",O34&","&P34,IF(R34="",O34&","&P34&","&Q34,IO34&","&P34&","&Q34&","&R34))) -> M3 | BL34: =IF(S34=0,"",S34) | BM34: =A34 -> 20089
A35: 40024 | B35: 030055-ZM2W-DS | C35: VH/W SE M/S STEP | D35: LGS | F35: 44538 | H35: 3x5.5 | I35: EA | J35: 5000 | K35: M3 | O35: M3 | W35: 0.68 | X35: 0.67 | Y35: 0 | Z35: 0 | AA35: 2 | AE35: W | AI35: 60 | AJ35: 1850260 | AK35: 0 | AN35: S18A SAIP (F) | AO35: 2.6 | AX35: 20211208 | AY35: 10[H/D],30[R/L],70[&gt;H/T],80[&gt;P/T],85[ST/ PK],99[P/K] | BG35: =IF(LEFT(AY35,2)="98","X","O") -> O | BH35: =IF(IFERROR(SEARCH("45",$AY35,1),0)>0,"Y","") | BI35: =IF(IFERROR(SEARCH("86",$AY35,1),0)>0,"Y","") | BJ35: =IF(L35="",K35,IF(M35="",K35&","&L35,IF(N35="",K35&","&L35&","&M35,K35&","&L35&","&M35&","&N35))) -> M3 | BK35: =IF(P35="",O35,IF(Q35="",O35&","&P35,IF(R35="",O35&","&P35&","&Q35,IO35&","&P35&","&Q35&","&R35))) -> M3 | BL35: =IF(S35=0,"",S35) | BM35: =A35 -> 40024
A36: 54001 | B36: 030060-B54W-ASZ | C36: BH(LARGE-ISO)SE M/S | D36: VEST | F36: 44792 | H36: M3*6 | I36: EA | J36: 5000 | K36: M3 | O36: M3 | W36: 0.63 | X36: 0.62 | Y36: 0 | Z36: 0 | AA36: 3 | AE36: W | AI36: 60 | AJ36: 4350260 | AK36: 0 | AN36: SCM435 PASAIP | AO36: 2.6 | AX36: 20220819 | AY36: 10[H/D],30[R/L],70[&gt;H/T],80[&gt;P/T],85[ST/ PK],99[P/K] | BG36: =IF(LEFT(AY36,2)="98","X","O") -> O | BH36: =IF(IFERROR(SEARCH("45",$AY36,1),0)>0,"Y","") | BI36: =IF(IFERROR(SEARCH("86",$AY36,1),0)>0,"Y","") | BJ36: =IF(L36="",K36,IF(M36="",K36&","&L36,IF(N36="",K36&","&L36&","&M36,K36&","&L36&","&M36&","&N36))) -> M3 | BK36: =IF(P36="",O36,IF(Q36="",O36&","&P36,IF(R36="",O36&","&P36&","&Q36,IO36&","&P36&","&Q36&","&R36))) -> M3 | BL36: =IF(S36=0,"",S36) | BM36: =A36 -> 54001
A37: 50303 | B37: 030060-B59B-MQ | C37: BH ± M/S | D37: BISG | F37: 43879 | H37: 3x6 | I37: EA | J37: 5000 | K37: M3 | O37: M3 | W37: 0.53 | X37: 0.55 | Y37: 0 | Z37: 0 | AA37: 801 | AB37: HV | AC37: 450-650 | AE37: B | AI37: 60 | AJ37: 1200260 | AK37: 0 | AN37: S12A HD | AO37: 2.6 | AX37: 20200218 | AY37: 10[H/D],30[R/L],70[&gt;H/T],80[&gt;P/T],85[ST/ PK],99[P/K] | BG37: =IF(LEFT(AY37,2)="98","X","O") -> O | BH37: =IF(IFERROR(SEARCH("45",$AY37,1),0)>0,"Y","") | BI37: =IF(IFERROR(SEARCH("86",$AY37,1),0)>0,"Y","") | BJ37: =IF(L37="",K37,IF(M37="",K37&","&L37,IF(N37="",K37&","&L37&","&M37,K37&","&L37&","&M37&","&N37))) -> M3 | BK37: =IF(P37="",O37,IF(Q37="",O37&","&P37,IF(R37="",O37&","&P37&","&Q37,IO37&","&P37&","&Q37&","&R37))) -> M3 | BL37: =IF(S37=0,"",S37) | BM37: =A37 -> 50303
A38: 51803 | B38: 030060-B61W-DQ | C38: BH T/S-2(NO CUTTING) | D38: NAMI | F38: 43819 | H38: 3x6 | I38: EA | J38: 20000 | K38: M3 | O38: M3 | W38: 0.59 | X38: 0.54 | Y38: 0 | Z38: 0 | AA38: 1 | AE38: W | AI38: 60 | AJ38: 1000246 | AK38: 0 | AN38: S10A HD | AO38: 2.46 | AX38: 20191220 | AY38: 10[H/D],30[R/L],70[&gt;H/T],80[&gt;P/T],85[ST/ PK],99[P/K] | BG38: =IF(LEFT(AY38,2)="98","X","O") -> O | BH38: =IF(IFERROR(SEARCH("45",$AY38,1),0)>0,"Y","") | BI38: =IF(IFERROR(SEARCH("86",$AY38,1),0)>0,"Y","") | BJ38: =IF(L38="",K38,IF(M38="",K38&","&L38,IF(N38="",K38&","&L38&","&M38,K38&","&L38&","&M38&","&N38))) -> M3 | BK38: =IF(P38="",O38,IF(Q38="",O38&","&P38,IF(R38="",O38&","&P38&","&Q38,IO38&","&P38&","&Q38&","&R38))) -> M3 | BL38: =IF(S38=0,"",S38) | BM38: =A38 -> 51803
A39: 51811 | B39: 030060-BB2B | C39: BH TTS-B | D39: NAMI | F39: 43965 | H39: 3x6 | I39: EA | J39: 20000 | K39: M3 | O39: M3 | W39: 0.51 | X39: 0.53 | Y39: 0 | Z39: 0 | AA39: 2 | AE39: B | AI39: 60 | AJ39: 1850246 | AK39: 0 | AL39: 0 | AN39: S18A SAIP (F) | AO39: 2.46 | AX39: 20200514 | AY39: 10[H/D],30[R/L],70[&gt;H/T],80[&gt;P/T],85[ST/ PK],99[P/K] | BG39: =IF(LEFT(AY39,2)="98","X","O") -> O | BH39: =IF(IFERROR(SEARCH("45",$AY39,1),0)>0,"Y","") | BI39: =IF(IFERROR(SEARCH("86",$AY39,1),0)>0,"Y","") | BJ39: =IF(L39="",K39,IF(M39="",K39&","&L39,IF(N39="",K39&","&L39&","&M39,K39&","&L39&","&M39&","&N39))) -> M3 | BK39: =IF(P39="",O39,IF(Q39="",O39&","&P39,IF(R39="",O39&","&P39&","&Q39,IO39&","&P39&","&Q39&","&R39))) -> M3 | BL39: =IF(S39=0,"",S39) | BM39: =A39 -> 51811
A40: 52107 | B40: 030060-BB2N | C40: BH TTS-B | D40: HANM | F40: 43775 | H40: 3x6 | I40: EA | J40: 5000 | K40: M3 | O40: M3 | W40: 0.51 | X40: 0.53 | Y40: 0 | Z40: 0 | AA40: 2 | AE40: N | AI40: 60 | AJ40: 1850246 | AK40: 0 | AL40: 0 | AN40: S18A SAIP (F) | AO40: 2.46 | AX40: 20191106 | AY40: 10[H/D],30[R/L],70[&gt;H/T],80[&gt;P/T],85[ST/ PK],99[P/K] | BG40: =IF(LEFT(AY40,2)="98","X","O") -> O | BH40: =IF(IFERROR(SEARCH("45",$AY40,1),0)>0,"Y","") | BI40: =IF(IFERROR(SEARCH("86",$AY40,1),0)>0,"Y","") | BJ40: =IF(L40="",K40,IF(M40="",K40&","&L40,IF(N40="",K40&","&L40&","&M40,K40&","&L40&","&M40&","&N40))) -> M3 | BK40: =IF(P40="",O40,IF(Q40="",O40&","&P40,IF(R40="",O40&","&P40&","&Q40,IO40&","&P40&","&Q40&","&R40))) -> M3 | BL40: =IF(S40=0,"",S40) | BM40: =A40 -> 52107
...

Sheet FG Stock
A1: công ty | B1: mã code | C1: Code s?n ph?m | D1: tên s?n ph?m | E1: quy cách | F1: code li?u | G1: d?ng | H1: t?n tháng tru?c | I1: nh?p | J1: xu?t | K1: di?u ch?nh | L1: s? lu?ng ch? dóng gói | M1: t?n | N1: giá | O1: ti?n t?n | P1: Ghi chú
A2: TBVN | B2: *N80130-PDEZ-S* | C2: #80130-PDEZ-S | D2: PH SDS SE | E2: #8x13 | F2: P02200325 | G2: 1.49 | H2: 782000 | I2: 0 | J2: 150000 | K2: 0 | M2: 632000 | O2: 0
A3: HPW | B3: *N80160-CD5H* | C3: #80160-CD5H | D3: PH/W SDS | E3: #8x16 | F3: 4100325 | G3: 1.53 | H3: 159500 | I3: 0 | J3: 0 | K3: 0 | M3: 159500 | O3: 91234000
A4: HPW | B4: *N80160-JD5H* | C4: #80160-JD5H | D4: FH SDS | E4: #8x16 | F4: 4100325 | G4: 1.17 | H4: 66000 | I4: 0 | J4: 0 | K4: 0 | M4: 66000 | O4: 37554000
A5: HSBK | B5: *N80180-F12Z-5P* | C5: #80180-F12Z-5P | D5: FL + T/S-1 PVC/W | E5: #8 x18 | F5: 1850330 | G5: 2.18 | H5: 216000 | I5: 0 | J5: 0 | K5: 0 | M5: 216000 | O5: 3456
A6: SHARP | B6: *020030-YB2B* | C6: 020030-YB2B | D6: FLATNESS TTS-B | E6: 2*3 | F6: 1850169 | G6: 0.11 | H6: 29181 | I6: 0 | J6: 0 | K6: 0 | M6: 29181 | O6: 0
A7: SCON | B7: *020050-P56H* | C7: 020050-P56H | D7: PH M/S (SUS304) | E7: M2*5 | F7: 3040160 | G7: 0.17 | H7: 100000 | I7: 0 | J7: 0 | K7: 0 | M7: 100000 | O7: 0
A8: SHARP | B8: *020060-B62W* | C8: 020060-B62W | D8: BH T/S-2(NO CUTTING) | E8: 2x6 | F8: 1850171 | G8: 0.2 | H8: 190000 | I8: 0 | J8: 25000 | K8: 0 | M8: 165000 | O8: 10560000
A9: SHARP | B9: *020060-PB2W* | C9: 020060-PB2W | D9: PH TTS-B | E9: 2x6 | F9: 1850169 | G9: 0.15 | H9: 103958 | I9: 0 | J9: 10000 | K9: 0 | M9: 93958 | O9: 0
A10: NAMI | B10: *020075-PP2B* | C10: 020075-PP2B | D10: PH TTS-P | E10: 2x7.5 | F10: 1850165 | G10: 0.17 | H10: 740000 | I10: 0 | J10: 300000 | K10: 0 | M10: 440000 | O10: 22880000
A11: SEHC | B11: *020130-Z06H* | C11: 020130-Z06H | D11: SHAFT HINGE | E11: 2x13 | F11: 3330020 | G11: 0.35 | H11: 160000 | I11: 0 | J11: 0 | K11: 0 | M11: 160000 | O11: 16480000
A12: NAMI | B12: *020170-P51W* | C12: 020170-P51W | D12: PH M/S | E12: 2x17 | F12: 1000169 | G12: 0.36 | H12: 550000 | I12: 0 | J12: 200000 | K12: 0 | M12: 350000 | O12: 0
A13: HSV | B13: *026080-0500-2F* | C13: 026080-0500-2F | D13: PLAIN WASHER | E13: 2.6x8.0x0.5T | F13: P15500001 | G13: 0.18 | H13: 104200 | I13: 0 | J13: 0 | K13: 0 | M13: 104200 | O13: 0
A14: HSV | B14: *027055-0780-3* | C14: 027055-0780-3 | D14: SPRING WASHER | E14: 2.7x5.5x0.7T | F14: P15400001 | G14: 0.08 | H14: 244798 | I14: 0 | J14: 167000 | K14: 0 | M14: 77798 | O14: 0
A15: HSV | B15: *027060-0600-2F* | C15: 027060-0600-2F | D15: PLAIN WASHER | E15: 2.7x6.0x0.6T | F15: P15500002 | G15: 0.07 | H15: 81298 | I15: 200000 | J15: 167000 | K15: 0 | M15: 114298 | O15: 0
A16: BRSG | B16: *030030-Z54B-H* | C16: 030030-Z54B-H | D16: LOWHEADBOLTSOCKET M3 | E16: M3*3 | F16: 4350260 | G16: 0.36 | H16: 10000 | I16: 0 | J16: 0 | K16: 0 | M16: 10000 | O16: 0
A17: HANM | B17: *030040-B51N-S* | C17: 030040-B51N-S | D17: BH M/S SE | E17: 3x4 | F17: 1000260 | G17: 0.45 | H17: 10000 | I17: 0 | J17: 0 | K17: 0 | M17: 10000 | O17: 920000
A18: HANM | B18: *030040-C51N* | C18: 030040-C51N | D18: PH/W M/S | E18: 3x4 | F18: 1000260 | G18: 0.54 | H18: 185000 | I18: 0 | J18: 0 | K18: 0 | M18: 185000 | O18: 20905000
A19: HANM | B19: *030040-P51N* | C19: 030040-P51N | D19: PH M/S | E19: 3x4 | F19: 1000260 | G19: 0.4 | H19: 17000 | I19: 0 | J19: 0 | K19: 0 | M19: 17000 | O19: 1394000
A20: NAMI | B20: *030045-B62W-Z* | C20: 030045-B62W-Z | D20: BH T/S-2(NO CUTTING) | E20: 3x4.5 | F20: 1850246 | G20: 0.45 | H20: 596739 | I20: 0 | J20: 0 | K20: 0 | M20: 596739 | O20: 26853255
A21: NAMI | B21: *030045-CB2W* | C21: 030045-CB2W | D21: PH/W TTS-B | E21: 3x4.5 | F21: 1850246 | G21: 0.67 | H21: 440000 | I21: 0 | J21: 100000 | K21: 0 | M21: 340000 | O21: 0
A22: NAMI | B22: *030046-B62W* | C22: 030046-B62W | D22: BH T/S-2(NO CUTTING) | E22: 3x4.6 | F22: 1850246 | G22: 0.55 | H22: 220000 | I22: 0 | J22: 0 | K22: 0 | M22: 220000 | O22: 0
A23: SEHC | B23: *030050-P52W-3N* | C23: 030050-P52W-3N | D23: PH M/S S/W | E23: M3x5 | F23: 1850260 | G23: 0.53 | H23: 446492 | I23: 0 | J23: 75860 | K23: 0 | M23: 370632 | O23: 0
A24: LGS | B24: *030055-ZM2W-DS* | C24: 030055-ZM2W-DS | D24: VH/W SE M/S STEP | E24: 3x5.5 | F24: 1850260 | G24: 0.67 | H24: 7500 | I24: 0 | J24: 0 | K24: 0 | M24: 7500 | O24: 0
A25: VEST | B25: *030060-B54W-ASZ* | C25: 030060-B54W-ASZ | D25: BH(LARGE-ISO)SE M/S | E25: M3*6 | F25: 4350260 | G25: 0.62 | H25: 2250000 | I25: 0 | J25: 0 | K25: 0 | M25: 2250000 | O25: 0
A26: BISG | B26: *030060-B59B-MQ* | C26: 030060-B59B-MQ | D26: BH ± M/S | E26: 3x6 | F26: 1200260 | G26: 0.55 | H26: 480000 | I26: 0 | J26: 200000 | K26: 0 | M26: 280000 | O26: 728
A27: NAMI | B27: *030060-B61W-DQ* | C27: 030060-B61W-DQ | D27: BH T/S-2(NO CUTTING) | E27: 3x6 | F27: 1000246 | G27: 0.54 | H27: 380000 | I27: 0 | J27: 300000 | K27: 0 | M27: 80000 | O27: 3680000
... A47: NAMI | B47: *030060-PB2W-AZ* | C47: 030060-PB2W-AZ | D47: PH (LARGE) TTS-B | E47: 3x6 | F47: 1850246 | G47: 0.52 | H47: 4660000 | I47: 3460000 | J47: 5000000 | K47: 0 | M47: 3120000 | O47: 121680000
A48: LGS | B48: *030060-V22W* | C48: 030060-V22W | D48: VH T/S-2S | F48: 1850246 | G48: 0.55 | H48: 40000 | I48: 0 | J48: 0 | K48: 0 | M48: 40000 | O48: 0
A49: PAWM | B49: *030080-B22W* | C49: 030080-B22W | D49: BH T/S - 2S | E49: 3x8 | F49: 1850246 | G49: 0.6 | H49: 305000 | I49: 0 | J49: 0 | K49: 0 | M49: 305000 | O49: 0
A50: BISG | B50: *030080-BB2B* | C50: 030080-BB2B | D50: BH TTS-B | E50: 3x8 | F50: 1850246 | G50: 0.58 | H50: 125000 | I50: 0 | J50: 0 | K50: 0 | M50: 125000 | O50: 375
A51: HANM | B51: *030080-BB2N* | C51: 030080-BB2N | D51: BH TTS-B | E51: 3x8 | F51: 1850246 | G51: 0.57 | H51: 170000 | I51: 0 | J51: 0 | K51: 0 | M51: 170000 | O51: 19210000
A52: SHARP | B52: *030080-CP5W* | C52: 030080-CP5W | D52: PH/W TTS-P (STS430) | E52: 3x8 | F52: 4300246 | G52: 0.68 | H52: 5000 | I52: 50000 | J52: 5000 | K52: 0 | M52: 50000 | O52: 0
A53: FRIW | B53: *030080-J52N* | C53: 030080-J52N | D53: FH(100) M/S | E53: M3x8 | F53: 1850260 | G53: 0.43 | H53: 0 | I53: 300000 | J53: 108000 | K53: 0 | M53: 192000 | O53: 0
A54: LGS | B54: *030080-J621* | C54: 030080-J621 | D54: FH T/S-2(NO CUTTING) | E54: 3x8 | F54: 1850246 | G54: 0.45 | H54: 295000 | I54: 0 | J54: 120000 | K54: 0 | M54: 175000 | O54: 10500000
A55: NAMI | B55: *030080-J62B* | C55: 030080-J62B | D55: FH T/S-2(NO CUTTING) | E55: 3x8 | F55: 1850246 | G55: 0.45 | H55: 65000 | I55: 0 | J55: 0 | K55: 0 | M55: 65000 | O55: 0
A56: NAMI | B56: *030080-J62N* | C56: 030080-J62N | D56: FH T/S-2(NO CUTTING) | E56: 3x8 | F56: 1850246 | G56: 0.44 | H56: 80000 | I56: 0 | J56: 0 | K56: 0 | M56: 80000 | O56: 0
A57: LGS | B57: *030080-JB2B* | C57: 030080-JB2B | D57: FH TTS-B | E57: 3*8 | F57: 1850246 | G57: 0.36 | H57: 415000 | I57: 0 | J57: 90000 | K57: 0 | M57: 325000 | O57: 0
A58: SHARP | B58: *030080-JP2B* | C58: 030080-JP2B | D58: FH TTS-P | E58: 3*8 | F58: 1850246 | G58: 0.43 | H58: 23366 | I58: 0 | J58: 0 | K58: 0 | M58: 23366 | O58: 0
A59: SHARP | B59: *030080-JP2W* | C59: 030080-JP2W | D59: FH TTS-P | E59: 3x8 | F59: 1850246 | G59: 0.38 | H59: 31711 | I59: 0 | J59: 0 | K59: 0 | M59: 31711 | O59: 0
...

Sheet NVL Stock
A1: NO | B1: Code | C1: Material | D1: Size (Ø) | E1: SL c?n(A) | F1: Pending(B) | G1: Main Stock(C) | H1: Line Stock(D) | I1: RMA Stock(E) | J1: Total Stock(C+D+E) | K1: Available(C+D) | L1: C?n mua(A-(B+C+D)) | N1: Loại NVL | O1: Stock
A2: 1 | B2: 1000169 | C2: S10A HD | D2: 1.69 | E2: 0 | F2: 0 | G2: 114 | H2: 0 | I2: 0 | J2: 114 | K2: 114 | L2: -114 | N2: =C2&D2 -> S10A HD1.69 | O2: =J2 -> 114
A3: 2 | B3: 1000215 | C3: S10A HD | D3: 2.15 | E3: 0 | F3: 0 | G3: 7 | H3: 0 | I3: 0 | J3: 7 | K3: 7 | L3: -7 | N3: =C3&D3 -> S10A HD2.15 | O3: =J3 -> 7
A4: 3 | B4: 1000218 | C4: S10A HD | D4: 2.18 | E4: 0 | F4: 0 | G4: 100 | H4: 0 | I4: 0 | J4: 100 | K4: 100 | L4: -100 | N4: =C4&D4 -> S10A HD2.18 | O4: =J4 -> 100
A5: 4 | B5: 1000225 | C5: S10A HD | D5: 2.25 | E5: 0 | F5: 0 | G5: 10 | H5: 0 | I5: 0 | J5: 10 | K5: 10 | L5: -10 | N5: =C5&D5 -> S10A HD2.25 | O5: =J5 -> 10
A6: 5 | B6: 1000246 | C6: S10A HD | D6: 2.46 | E6: 178 | F6: 0 | G6: 1142 | H6: 0 | I6: 0 | J6: 1142 | K6: 1142 | L6: -964 | N6: =C6&D6 -> S10A HD2.46 | O6: =J6 -> 1142
A7: 6 | B7: 1000260 | C7: S10A HD | D7: 2.6 | E7: 0 | F7: 0 | G7: 330 | H7: 0 | I7: 0 | J7: 330 | K7: 330 | L7: -330 | N7: =C7&D7 -> S10A HD2.6 | O7: =J7 -> 330
A8: 7 | B8: 1000295 | C8: S10A HD | D8: 2.95 | E8: 0 | F8: 0 | G8: 5 | H8: 0 | I8: 0 | J8: 5 | K8: 5 | L8: -5 | N8: =C8&D8 -> S10A HD2.95 | O8: =J8 -> 5
A9: 8 | B9: 1000300 | C9: S10A HD | D9: 3 | E9: 0 | F9: 0 | G9: 18 | H9: 0 | I9: 0 | J9: 18 | K9: 18 | L9: -18 | N9: =C9&D9 -> S10A HD3 | O9: =J9 -> 18
A10: 9 | B10: 1000320 | C10: S10A HD | D10: 3.2 | E10: 0 | F10: 0 | G10: 631 | H10: 0 | I10: 0 | J10: 631 | K10: 631 | L10: -631 | N10: =C10&D10 -> S10A HD3.2 | O10: =J10 -> 631
A11: 10 | B11: 1000325 | C11: S10A HD | D11: 3.25 | E11: 0 | F11: 0 | G11: 249 | H11: 0 | I11: 0 | J11: 249 | K11: 249 | L11: -249 | N11: =C11&D11 -> S10A HD3.25 | O11: =J11 -> 249
A12: 11 | B12: 1000345 | C12: S10A HD | D12: 3.45 | E12: 214 | F12: 0 | G12: 700 | H12: 37 | I12: 0 | J12: 737 | K12: 737 | L12: -523 | N12: =C12&D12 -> S10A HD3.45 | O12: =J12 -> 737
